Workbook
Name CreateID: _xlfn.LAMBDA(_xlpm._header,_xlpm._column,_xlpm._test,IF(ROW()=ROW(_xlpm._header)+1,0,INDEX(_xlpm._column,ROW()-1))+IF(_xlpm._test,1,0))
Name CreateSearchString: _xlfn.LAMBDA(_xlpm._in,IF(_xlpm._in="","",","&SUBSTITUTE(SUBSTITUTE(_xlpm._in,CHAR(10),"")," ","")&IF(RIGHT(_xlpm._in,1)=",","",",")))
Name EscapeString: _xlfn.LAMBDA(_xlpm._string,SUBSTITUTE(_xlpm._string,CHAR(34),"'"))
Name GenerateRationale: _xlfn.LAMBDA(_xlpm._in,OFFSET(_xlpm._in,0,0)&": "&CHAR(10)&OFFSET(_xlpm._in,0,1)&": "&CHAR(10)&OFFSET(_xlpm._in,0,2)&": "&CHAR(10)&OFFSET(_xlpm._in,0,3)&": "&CHAR(10)&OFFSET(_xlpm._in,0,4)&": ")
Name GetReferenceText: _xlfn.LAMBDA(_xlpm._reference,_xlfn.LET(_xlpm._full,CELL("address",_xlpm._reference),"'"&SUBSTITUTE(SUBSTITUTE(RIGHT(_xlpm._full,LEN(_xlpm._full)-FIND("]",_xlpm._full)),"'!","!"),"!","'!")))
Name GetSheetName: _xlfn.LAMBDA(_xlpm._shadowIDHeader,_xlfn.LET(_xlpm._sheetAddress,CELL("filename",_xlpm._shadowIDHeader),RIGHT(_xlpm._sheetAddress,LEN(_xlpm._sheetAddress)-FIND("]",_xlpm._sheetAddress))))
Name JSON_Questionnaire: JSON!$C$7
Name JSON_ResultSummary: JSON!$C$9
Name JSON_RiskTreatment: JSON!$C$8
Name LookupNames: _xlfn.LAMBDA(_xlpm._in,_xlpm._range,RemoveDelimiter(GetValues(_xlpm._in,_xlpm._range," ",","&CHAR(10),TRUE),","&CHAR(10)))
Name PrintDate: _xlfn.LAMBDA(_xlpm._date,TEXT(DAY(_xlpm._date),"00")&"."&TEXT(MONTH(_xlpm._date),"00")&"."&TEXT(YEAR(_xlpm._date),"0000"))
Name RemoveDelimiter: _xlfn.LAMBDA(_xlpm._in,_xlpm._delimiter,IF(_xlpm._in="","",SUBSTITUTE(SUBSTITUTE(_xlpm._in&CHAR(1),_xlpm._delimiter&CHAR(1),""),CHAR(1),"")))
Name RemoveFirstElement: _xlfn.LAMBDA(_xlpm._in,IF(_xlpm._in="","",SUBSTITUTE(SUBSTITUTE(SUBSTITUTE("#"&_xlpm._in,",",",#"),"#"&LEFT(_xlpm._in,FIND(",",_xlpm._in)),""),"#","")))
Name SanitizeInput: _xlfn.LAMBDA(_xlpm._in,IF(_xlpm._in="","",SUBSTITUTE(SUBSTITUTE(_xlpm._in,CHAR(10),"")," ","")&IF(RIGHT(_xlpm._in,1)=",","",",")))
Name SimpleLookup: _xlfn.LAMBDA(_xlpm._id,_xlpm._range,VLOOKUP(_xlpm._id,_xlpm._range,COLUMNS(_xlpm._range),FALSE))

Sheet License
A2: Questionnaire-Based Assessment (QuBA) © 2025 by SICK AG and Fraunhofer-Institut für Angewandte und Integrierte Sicherheit AISEC is licensed under CC BY-SA 4.0. To view a copy of this license, visit https://creativecommons.org/licenses/by-sa/4.0/

Sheet README
A1: Quick Start Guide (See below for more detailed explanations)
B2: {=HYPERLINK("#"&GetReferenceText(Definitions!$C$4),"(0) Tailor the assessment model and the catalogs.")} -> (0) Tailor the assessment model and the catalogs.
B3: Make sure you tailor the document, especially the assessment model contained in the Definitions sheet and the catalogs, to your organization. For example, adapt the exemplary risk matrix to a matrix that fits your organization and its context.
B4: {=HYPERLINK("#"&GetReferenceText(Documentation!$C$2),"(1) Provide basic information in the Documentation sheet.")} -> (1) Provide basic information in the Documentation sheet.
B5: {=HYPERLINK("#"&GetReferenceText(Questionnaire!$C$6),"(2) Answer the questions in the Questionnaire sheet. Fill all marked boxes.")} -> (2) Answer the questions in the Questionnaire sheet. Fill all marked boxes.
B6: {=HYPERLINK("#"&GetReferenceText(Risks!$A$2),"(3) Ensure that the table in the Risks sheet is large enough to calculate all attack paths.")} -> (3) Ensure that the table in the Risks sheet is large enough to calculate all attack paths.
B7: If the message "Please enlarge the table to calculate all risks!" is displayed, then follow these steps: (1) Click on the blue triangle in the bottom right corner of the table, above the area colored in red. (2) Hold the left mouse button and drag the mouse downward until the red area is covered.
B8: {=HYPERLINK("#"&GetReferenceText(Mitigation!$J$3),"(4) Assign assumptions and countermeasures mitigating specific attack steps in the Mitigation sheet.")} -> (4) Assign assumptions and countermeasures mitigating specific attack steps in the Mitigation sheet.
B9: Recommendation: Copy the column Proposed Active Assumptions and paste as values into the column C and A IDs. These assumptions match the answers provided in the questionnnaire. See below for additional information.
B10: {=HYPERLINK("#"&GetReferenceText('Risk Treatment'!$A$5),"(5) Make risk treatment decisions in the Risk Treatment sheet.")} -> (5) Make risk treatment decisions in the Risk Treatment sheet.
A12: General Remarks
B13: * Whenever several items can be referenced, use comma-separated lists, denoted as CSV in the explanations below.
B14: * Some cells are restricted to choosing from a pre-defined list of options, denoted by drop-down menu in the explanations below.
B15: * All comment columns that accept text can be used with the Tasks feature (see the explanation for the Tasks sheet).
B16: * When copying, always paste as values!
B17: * For all questions that contain several criteria (e.g., "Is the access to the network restricted and are the devices in the network considered as trustworthy?":
B18: Only select "Yes" as an answer if all criteria a true (in this case, access is restricted and the devices are trustworthy).
B19: * This document requires the Microsoft 365 version of Excel
A21: Sheet Color | B21: Explanation
A22: Black | B22: This readme.
A23: Light Grey | B23: Catalogs - these are versioned and centrally managed. Do not edit during an analysis.
A24: Dark Grey | B24: Fill these sheets to complete the analysis.
A25: Blue | B25: Calculation and presentation of results.
A26: Green | B26: The summary of the resulting assumptions and countermeasures, including IDs for the external catalog, if available.
A28: Text Format | B28: Explanation
A29: White | B29: Contents of the analysis or the template. May be text or a formula.
A30: Green | B30: Calculated values, do not edit as the formula is included in template version management.
A31: Light Green | B31: The target of a link from the Tasks sheet (typically a TODO).
A32: Light Green | B32: A link.
A33: Lime | B33: Highlights the sheets that must be filled in an analysis.
A35: Detailed explanations for each sheet
A36: Sheet | B36: Column | C36: Explanation | D36: Comment | E36: Sheet Name | F36: Column Letter | G36: Header Row | H36: Sheet # | I36: Column Original Name | K36: Column Header Address | L36: Explicit Link Text | M36: Additional information
A37: {=IF(INDEX($H:$H,ROW()-1)<>$H37,$E37,"")} -> Version History | B37: {=IF($K37="","",_xlfn.LET(_xlpm._fullName,IF($L37="",SUBSTITUTE(SUBSTITUTE(INDIRECT($K37),CHAR(10)," ")," "," "),$L37),_xlpm._truncatedName,IF(LEN(_xlpm._fullName)>250,LEFT(_xlpm._fullName,250)&"[…]",_xlpm._fullName),HYPERLINK("#'"&$E37&"'!"&$F37&$G37,_xlpm._truncatedName)))} -> Template Version History | C37: A version history for the template (independent of the assessment). | E37: =IF($K37="","",_xlfn.LET(_xlpm._in,$K37,_xlpm._start,FIND("]",_xlpm._in)+1,SUBSTITUTE(MID(_xlpm._in,_xlpm._start,FIND("!",_xlpm._in)-_xlpm._start),"'",""))) -> Version History | F37: =IF($K37="","",_xlfn.LET(_xlpm._in,SUBSTITUTE($K37,"$","§",1),_xlpm._start,FIND("§",_xlpm._in)+1,SUBSTITUTE(MID(_xlpm._in,_xlpm._start,FIND("$",_xlpm._in)-_xlpm._start),"'",""))) -> B | G37: =IF($K37="","",RIGHT($K37,LEN($K37)-FIND("$",SUBSTITUTE($K37,"$","§",1)))) -> 1 | H37: {=CreateID($H$36,$H:$H,$E37<>INDEX($E:$E,ROW()-1))} -> 1 | I37: {=INDIRECT($K37)} -> Template Version History | K37: {=CELL("address",'Version History'!$B$1)} -> '[QuBA-libre.xlsx]Version History'!$B$1
A38: {=IF(INDEX($H:$H,ROW()-1)<>$H38,$E38,"")} | B38: {=IF($K38="","",_xlfn.LET(_xlpm._fullName,IF($L38="",SUBSTITUTE(SUBSTITUTE(INDIRECT($K38),CHAR(10)," ")," "," "),$L38),_xlpm._truncatedName,IF(LEN(_xlpm._fullName)>250,LEFT(_xlpm._fullName,250)&"[…]",_xlpm._fullName),HYPERLINK("#'"&$E38&"'!"&$F38&$G38,_xlpm._truncatedName)))} -> Definitions and Damage Scenarios Version History | C38: A version history for the Definitions sheet. Note that this usually relates to changes in the assessment model. | E38: =IF($K38="","",_xlfn.LET(_xlpm._in,$K38,_xlpm._start,FIND("]",_xlpm._in)+1,SUBSTITUTE(MID(_xlpm._in,_xlpm._start,FIND("!",_xlpm._in)-_xlpm._start),"'",""))) -> Version History | F38: =IF($K38="","",_xlfn.LET(_xlpm._in,SUBSTITUTE($K38,"$","§",1),_xlpm._start,FIND("§",_xlpm._in)+1,SUBSTITUTE(MID(_xlpm._in,_xlpm._start,FIND("$",_xlpm._in)-_xlpm._start),"'",""))) -> B | G38: =IF($K38="","",RIGHT($K38,LEN($K38)-FIND("$",SUBSTITUTE($K38,"$","§",1)))) -> 5 | H38: {=CreateID($H$36,$H:$H,$E38<>INDEX($E:$E,ROW()-1))} -> 1 | I38: {=INDIRECT($K38)} -> Definitions and Damage Scenarios Version History | K38: {=CELL("address",'Version History'!$B$5)} -> '[QuBA-libre.xlsx]Version History'!$B$5
A39: {=IF(INDEX($H:$H,ROW()-1)<>$H39,$E39,"")} | B39: {=IF($K39="","",_xlfn.LET(_xlpm._fullName,IF($L39="",SUBSTITUTE(SUBSTITUTE(INDIRECT($K39),CHAR(10)," ")," "," "),$L39),_xlpm._truncatedName,IF(LEN(_xlpm._fullName)>250,LEFT(_xlpm._fullName,250)&"[…]",_xlpm._fullName),HYPERLINK("#'"&$E39&"'!"&$F39&$G39,_xlpm._truncatedName)))} -> Attack Steps Version History | C39: A version history for the attack step catalog. | E39: =IF($K39="","",_xlfn.LET(_xlpm._in,$K39,_xlpm._start,FIND("]",_xlpm._in)+1,SUBSTITUTE(MID(_xlpm._in,_xlpm._start,FIND("!",_xlpm._in)-_xlpm._start),"'",""))) -> Version History | F39: =IF($K39="","",_xlfn.LET(_xlpm._in,SUBSTITUTE($K39,"$","§",1),_xlpm._start,FIND("§",_xlpm._in)+1,SUBSTITUTE(MID(_xlpm._in,_xlpm._start,FIND("$",_xlpm._in)-_xlpm._start),"'",""))) -> B | G39: =IF($K39="","",RIGHT($K39,LEN($K39)-FIND("$",SUBSTITUTE($K39,"$","§",1)))) -> 9 | H39: {=CreateID($H$36,$H:$H,$E39<>INDEX($E:$E,ROW()-1))} -> 1 | I39: {=INDIRECT($K39)} -> Attack Steps Version History | K39: {=CELL("address",'Version History'!$B$9)} -> '[QuBA-libre.xlsx]Version History'!$B$9
A40: {=IF(INDEX($H:$H,ROW()-1)<>$H40,$E40,"")} | B40: {=IF($K40="","",_xlfn.LET(_xlpm._fullName,IF($L40="",SUBSTITUTE(SUBSTITUTE(INDIRECT($K40),CHAR(10)," ")," "," "),$L40),_xlpm._truncatedName,IF(LEN(_xlpm._fullName)>250,LEFT(_xlpm._fullName,250)&"[…]",_xlpm._fullName),HYPERLINK("#'"&$E40&"'!"&$F40&$G40,_xlpm._truncatedName)))} -> Assumptions Version History | C40: A version history for the assumption catalog. | E40: =IF($K40="","",_xlfn.LET(_xlpm._in,$K40,_xlpm._start,FIND("]",_xlpm._in)+1,SUBSTITUTE(MID(_xlpm._in,_xlpm._start,FIND("!",_xlpm._in)-_xlpm._start),"'",""))) -> Version History | F40: =IF($K40="","",_xlfn.LET(_xlpm._in,SUBSTITUTE($K40,"$","§",1),_xlpm._start,FIND("§",_xlpm._in)+1,SUBSTITUTE(MID(_xlpm._in,_xlpm._start,FIND("$",_xlpm._in)-_xlpm._start),"'",""))) -> B | G40: =IF($K40="","",RIGHT($K40,LEN($K40)-FIND("$",SUBSTITUTE($K40,"$","§",1)))) -> 13 | H40: {=CreateID($H$36,$H:$H,$E40<>INDEX($E:$E,ROW()-1))} -> 1 | I40: {=INDIRECT($K40)} -> Assumptions Version History | K40: {=CELL("address",'Version History'!$B$13)} -> '[QuBA-libre.xlsx]Version History'!$B$13
A41: {=IF(INDEX($H:$H,ROW()-1)<>$H41,$E41,"")} | B41: {=IF($K41="","",_xlfn.LET(_xlpm._fullName,IF($L41="",SUBSTITUTE(SUBSTITUTE(INDIRECT($K41),CHAR(10)," ")," "," "),$L41),_xlpm._truncatedName,IF(LEN(_xlpm._fullName)>250,LEFT(_xlpm._fullName,250)&"[…]",_xlpm._fullName),HYPERLINK("#'"&$E41&"'!"&$F41&$G41,_xlpm._truncatedName)))} -> Countermeasures Version History | C41: A version history for the countermeasure catalog. | E41: =IF($K41="","",_xlfn.LET(_xlpm._in,$K41,_xlpm._start,FIND("]",_xlpm._in)+1,SUBSTITUTE(MID(_xlpm._in,_xlpm._start,FIND("!",_xlpm._in)-_xlpm._start),"'",""))) -> Version History | F41: =IF($K41="","",_xlfn.LET(_xlpm._in,SUBSTITUTE($K41,"$","§",1),_xlpm._start,FIND("§",_xlpm._in)+1,SUBSTITUTE(MID(_xlpm._in,_xlpm._start,FIND("$",_xlpm._in)-_xlpm._start),"'",""))) -> B | G41: =IF($K41="","",RIGHT($K41,LEN($K41)-FIND("$",SUBSTITUTE($K41,"$","§",1)))) -> 17 | H41: {=CreateID($H$36,$H:$H,$E41<>INDEX($E:$E,ROW()-1))} -> 1 | I41: {=INDIRECT($K41)} -> Countermeasures Version History | K41: {=CELL("address",'Version History'!$B$17)} -> '[QuBA-libre.xlsx]Version History'!$B$17
A42: {=IF(INDEX($H:$H,ROW()-1)<>$H42,$E42,"")} -> Definitions | B42: {=IF($K42="","",_xlfn.LET(_xlpm._fullName,IF($L42="",SUBSTITUTE(SUBSTITUTE(INDIRECT($K42),CHAR(10)," ")," "," "),$L42),_xlpm._truncatedName,IF(LEN(_xlpm._fullName)>250,LEFT(_xlpm._fullName,250)&"[…]",_xlpm._fullName),HYPERLINK("#'"&$E42&"'!"&$F42&$G42,_xlpm._truncatedName)))} -> Yes / No | C42: Defines the answers yes and no for the Questionnaire sheet. | E42: =IF($K42="","",_xlfn.LET(_xlpm._in,$K42,_xlpm._start,FIND("]",_xlpm._in)+1,SUBSTITUTE(MID(_xlpm._in,_xlpm._start,FIND("!",_xlpm._in)-_xlpm._start),"'",""))) -> Definitions | F42: =IF($K42="","",_xlfn.LET(_xlpm._in,SUBSTITUTE($K42,"$","§",1),_xlpm._start,FIND("§",_xlpm._in)+1,SUBSTITUTE(MID(_xlpm._in,_xlpm._start,FIND("$",_xlpm._in)-_xlpm._start),"'",""))) -> A | G42: =IF($K42="","",RIGHT($K42,LEN($K42)-FIND("$",SUBSTITUTE($K42,"$","§",1)))) -> 2 | H42: {=CreateID($H$36,$H:$H,$E42<>INDEX($E:$E,ROW()-1))} -> 2 | I42: {=INDIRECT($K42)} -> Yes / No | K42: {=CELL("address",Definitions!$A$2)} -> '[QuBA-libre.xlsx]Definitions'!$A$2
A43: {=IF(INDEX($H:$H,ROW()-1)<>$H43,$E43,"")} | B43: {=IF($K43="","",_xlfn.LET(_xlpm._fullName,IF($L43="",SUBSTITUTE(SUBSTITUTE(INDIRECT($K43),CHAR(10)," ")," "," "),$L43),_xlpm._truncatedName,IF(LEN(_xlpm._fullName)>250,LEFT(_xlpm._fullName,250)&"[…]",_xlpm._fullName),HYPERLINK("#'"&$E43&"'!"&$F43&$G43,_xlpm._truncatedName)))} -> Company Name | C43: Defines the name of the company. | E43: =IF($K43="","",_xlfn.LET(_xlpm._in,$K43,_xlpm._start,FIND("]",_xlpm._in)+1,SUBSTITUTE(MID(_xlpm._in,_xlpm._start,FIND("!",_xlpm._in)-_xlpm._start),"'",""))) -> Definitions | F43: =IF($K43="","",_xlfn.LET(_xlpm._in,SUBSTITUTE($K43,"$","§",1),_xlpm._start,FIND("§",_xlpm._in)+1,SUBSTITUTE(MID(_xlpm._in,_xlpm._start,FIND("$",_xlpm._in)-_xlpm._start),"'",""))) -> C | G43: =IF($K43="","",RIGHT($K43,LEN($K43)-FIND("$",SUBSTITUTE($K43,"$","§",1)))) -> 2 | H43: {=CreateID($H$36,$H:$H,$E43<>INDEX($E:$E,ROW()-1))} -> 2 | I43: {=INDIRECT($K43)} -> Company Name | K43: {=CELL("address",Definitions!$C$2)} -> '[QuBA-libre.xlsx]Definitions'!$C$2
A44: {=IF(INDEX($H:$H,ROW()-1)<>$H44,$E44,"")} | B44: {=IF($K44="","",_xlfn.LET(_xlpm._fullName,IF($L44="",SUBSTITUTE(SUBSTITUTE(INDIRECT($K44),CHAR(10)," ")," "," "),$L44),_xlpm._truncatedName,IF(LEN(_xlpm._fullName)>250,LEFT(_xlpm._fullName,250)&"[…]",_xlpm._fullName),HYPERLINK("#'"&$E44&"'!"&$F44&$G44,_xlpm._truncatedName)))} -> Damage Categories | C44: Defines damage categories in accordance with the OEM's security risk assessment method to be used in the Questionnaire sheet. | E44: =IF($K44="","",_xlfn.LET(_xlpm._in,$K44,_xlpm._start,FIND("]",_xlpm._in)+1,SUBSTITUTE(MID(_xlpm._in,_xlpm._start,FIND("!",_xlpm._in)-_xlpm._start),"'",""))) -> Definitions | F44: =IF($K44="","",_xlfn.LET(_xlpm._in,SUBSTITUTE($K44,"$","§",1),_xlpm._start,FIND("§",_xlpm._in)+1,SUBSTITUTE(MID(_xlpm._in,_xlpm._start,FIND("$",_xlpm._in)-_xlpm._start),"'",""))) -> E | G44: =IF($K44="","",RIGHT($K44,LEN($K44)-FIND("$",SUBSTITUTE($K44,"$","§",1)))) -> 2 | H44: {=CreateID($H$36,$H:$H,$E44<>INDEX($E:$E,ROW()-1))} -> 2 | I44: {=INDIRECT($K44)} -> Damage Categories | K44: {=CELL("address",Definitions!$E$2)} -> '[QuBA-libre.xlsx]Definitions'!$E$2
...

Sheet Version History
A1: {=_xlfn.LAMBDA(_xlpm._thisSheet,_xlpm._columnName,_xlpm._readmeSheetsRange,_xlpm._columnSearchHeader,_xlpm._columnNameHeader,_xlfn.LET(_xlpm._rowColumnNameHeader,ROW(_xlpm._columnNameHeader),_xlpm._startOfSheetExplanations,MATCH(_xlpm._thisSheet,_xlpm._readmeSheetsRange,0),_xlpm._numberOfEntriesForSheet,COUNTIF(_xlpm._readmeSheetsRange,_xlpm._thisSheet),_xlpm._searchRange,OFFSET(_xlpm._columnSearchHeader,_xlpm._startOfSheetExplanations-_xlpm._rowColumnNameHeader,0,_xlpm._numberOfEntriesForSheet,1),_xlpm._entryOffset,MATCH(_xlpm._columnName,_xlpm._searchRange,0)-1+_xlpm._startOfSheetExplanations,HYPERLINK("#'"&Helper!$G$2&"'!"&CHAR(CODE("A")+COLUMN(_xlpm._columnNameHeader)-1)&_xlpm._entryOffset,Definitions!$AY$4)))(Helper!$G$20,$B1,README!$E:$E,README!$I$36,README!$B$36)} -> ◈ | B1: Template Version History
B2: Date | C2: Version | D2: Changes | E2: Author | F2: Is last
B3: 45870 | C3: 1.0.0 | D3: Initial version | E3: qubalibre@SICK.de riskassessments@aisec.fraunhofer.de | F3: {=_xlfn.LAMBDA(_xlpm._dateCell,AND(_xlpm._dateCell<>"",OFFSET(_xlpm._dateCell,1,0)=""))($B3)} -> TRUE
A5: {=_xlfn.LAMBDA(_xlpm._thisSheet,_xlpm._columnName,_xlpm._readmeSheetsRange,_xlpm._columnSearchHeader,_xlpm._columnNameHeader,_xlfn.LET(_xlpm._rowColumnNameHeader,ROW(_xlpm._columnNameHeader),_xlpm._startOfSheetExplanations,MATCH(_xlpm._thisSheet,_xlpm._readmeSheetsRange,0),_xlpm._numberOfEntriesForSheet,COUNTIF(_xlpm._readmeSheetsRange,_xlpm._thisSheet),_xlpm._searchRange,OFFSET(_xlpm._columnSearchHeader,_xlpm._startOfSheetExplanations-_xlpm._rowColumnNameHeader,0,_xlpm._numberOfEntriesForSheet,1),_xlpm._entryOffset,MATCH(_xlpm._columnName,_xlpm._searchRange,0)-1+_xlpm._startOfSheetExplanations,HYPERLINK("#'"&Helper!$G$2&"'!"&CHAR(CODE("A")+COLUMN(_xlpm._columnNameHeader)-1)&_xlpm._entryOffset,Definitions!$AY$4)))(Helper!$G$20,$B5,README!$E:$E,README!$I$36,README!$B$36)} -> ◈ | B5: Definitions and Damage Scenarios Version History
B6: Date | D6: Changes | F6: Is last
B7: 45870 | D7: Initial catalog | F7: {=_xlfn.LAMBDA(_xlpm._dateCell,AND(_xlpm._dateCell<>"",OFFSET(_xlpm._dateCell,1,0)=""))($B7)} -> TRUE
A9: {=_xlfn.LAMBDA(_xlpm._thisSheet,_xlpm._columnName,_xlpm._readmeSheetsRange,_xlpm._columnSearchHeader,_xlpm._columnNameHeader,_xlfn.LET(_xlpm._rowColumnNameHeader,ROW(_xlpm._columnNameHeader),_xlpm._startOfSheetExplanations,MATCH(_xlpm._thisSheet,_xlpm._readmeSheetsRange,0),_xlpm._numberOfEntriesForSheet,COUNTIF(_xlpm._readmeSheetsRange,_xlpm._thisSheet),_xlpm._searchRange,OFFSET(_xlpm._columnSearchHeader,_xlpm._startOfSheetExplanations-_xlpm._rowColumnNameHeader,0,_xlpm._numberOfEntriesForSheet,1),_xlpm._entryOffset,MATCH(_xlpm._columnName,_xlpm._searchRange,0)-1+_xlpm._startOfSheetExplanations,HYPERLINK("#'"&Helper!$G$2&"'!"&CHAR(CODE("A")+COLUMN(_xlpm._columnNameHeader)-1)&_xlpm._entryOffset,Definitions!$AY$4)))(Helper!$G$20,$B9,README!$E:$E,README!$I$36,README!$B$36)} -> ◈ | B9: Attack Steps Version History
B10: Date | D10: Changes | F10: Is last
B11: 45870 | D11: Initial catalog | F11: {=_xlfn.LAMBDA(_xlpm._dateCell,AND(_xlpm._dateCell<>"",OFFSET(_xlpm._dateCell,1,0)=""))($B11)} -> TRUE
A13: {=_xlfn.LAMBDA(_xlpm._thisSheet,_xlpm._columnName,_xlpm._readmeSheetsRange,_xlpm._columnSearchHeader,_xlpm._columnNameHeader,_xlfn.LET(_xlpm._rowColumnNameHeader,ROW(_xlpm._columnNameHeader),_xlpm._startOfSheetExplanations,MATCH(_xlpm._thisSheet,_xlpm._readmeSheetsRange,0),_xlpm._numberOfEntriesForSheet,COUNTIF(_xlpm._readmeSheetsRange,_xlpm._thisSheet),_xlpm._searchRange,OFFSET(_xlpm._columnSearchHeader,_xlpm._startOfSheetExplanations-_xlpm._rowColumnNameHeader,0,_xlpm._numberOfEntriesForSheet,1),_xlpm._entryOffset,MATCH(_xlpm._columnName,_xlpm._searchRange,0)-1+_xlpm._startOfSheetExplanations,HYPERLINK("#'"&Helper!$G$2&"'!"&CHAR(CODE("A")+COLUMN(_xlpm._columnNameHeader)-1)&_xlpm._entryOffset,Definitions!$AY$4)))(Helper!$G$20,$B13,README!$E:$E,README!$I$36,README!$B$36)} -> ◈ | B13: Assumptions Version History
B14: Date | D14: Changes | F14: Is last
B15: 45870 | D15: Initial catalog | F15: {=_xlfn.LAMBDA(_xlpm._dateCell,AND(_xlpm._dateCell<>"",OFFSET(_xlpm._dateCell,1,0)=""))($B15)} -> TRUE
A17: {=_xlfn.LAMBDA(_xlpm._thisSheet,_xlpm._columnName,_xlpm._readmeSheetsRange,_xlpm._columnSearchHeader,_xlpm._columnNameHeader,_xlfn.LET(_xlpm._rowColumnNameHeader,ROW(_xlpm._columnNameHeader),_xlpm._startOfSheetExplanations,MATCH(_xlpm._thisSheet,_xlpm._readmeSheetsRange,0),_xlpm._numberOfEntriesForSheet,COUNTIF(_xlpm._readmeSheetsRange,_xlpm._thisSheet),_xlpm._searchRange,OFFSET(_xlpm._columnSearchHeader,_xlpm._startOfSheetExplanations-_xlpm._rowColumnNameHeader,0,_xlpm._numberOfEntriesForSheet,1),_xlpm._entryOffset,MATCH(_xlpm._columnName,_xlpm._searchRange,0)-1+_xlpm._startOfSheetExplanations,HYPERLINK("#'"&Helper!$G$2&"'!"&CHAR(CODE("A")+COLUMN(_xlpm._columnNameHeader)-1)&_xlpm._entryOffset,Definitions!$AY$4)))(Helper!$G$20,$B17,README!$E:$E,README!$I$36,README!$B$36)} -> ◈ | B17: Countermeasures Version History
B18: Date | D18: Changes | F18: Is last
B19: 45870 | D19: Initial catalog | F19: {=_xlfn.LAMBDA(_xlpm._dateCell,AND(_xlpm._dateCell<>"",OFFSET(_xlpm._dateCell,1,0)=""))($B19)} -> TRUE

Sheet Definitions
A1: {=_xlfn.LAMBDA(_xlpm._thisSheet,_xlpm._columnName,_xlpm._readmeSheetsRange,_xlpm._columnSearchHeader,_xlpm._columnNameHeader,_xlfn.LET(_xlpm._rowColumnNameHeader,ROW(_xlpm._columnNameHeader),_xlpm._startOfSheetExplanations,MATCH(_xlpm._thisSheet,_xlpm._readmeSheetsRange,0),_xlpm._numberOfEntriesForSheet,COUNTIF(_xlpm._readmeSheetsRange,_xlpm._thisSheet),_xlpm._searchRange,OFFSET(_xlpm._columnSearchHeader,_xlpm._startOfSheetExplanations-_xlpm._rowColumnNameHeader,0,_xlpm._numberOfEntriesForSheet,1),_xlpm._entryOffset,MATCH(_xlpm._columnName,_xlpm._searchRange,0)-1+_xlpm._startOfSheetExplanations,HYPERLINK("#'"&Helper!$G$2&"'!"&CHAR(CODE("A")+COLUMN(_xlpm._columnNameHeader)-1)&_xlpm._entryOffset,Definitions!$AY$4)))(Helper!$G$3,A$2,README!$E:$E,README!$I$36,README!$B$36)} -> ◈ | C1: {=_xlfn.LAMBDA(_xlpm._thisSheet,_xlpm._columnName,_xlpm._readmeSheetsRange,_xlpm._columnSearchHeader,_xlpm._columnNameHeader,_xlfn.LET(_xlpm._rowColumnNameHeader,ROW(_xlpm._columnNameHeader),_xlpm._startOfSheetExplanations,MATCH(_xlpm._thisSheet,_xlpm._readmeSheetsRange,0),_xlpm._numberOfEntriesForSheet,COUNTIF(_xlpm._readmeSheetsRange,_xlpm._thisSheet),_xlpm._searchRange,OFFSET(_xlpm._columnSearchHeader,_xlpm._startOfSheetExplanations-_xlpm._rowColumnNameHeader,0,_xlpm._numberOfEntriesForSheet,1),_xlpm._entryOffset,MATCH(_xlpm._columnName,_xlpm._searchRange,0)-1+_xlpm._startOfSheetExplanations,HYPERLINK("#'"&Helper!$G$2&"'!"&CHAR(CODE("A")+COLUMN(_xlpm._columnNameHeader)-1)&_xlpm._entryOffset,Definitions!$AY$4)))(Helper!$G$3,C$2,README!$E:$E,README!$I$36,README!$B$36)} -> ◈ | E1: {=_xlfn.LAMBDA(_xlpm._thisSheet,_xlpm._columnName,_xlpm._readmeSheetsRange,_xlpm._columnSearchHeader,_xlpm._columnNameHeader,_xlfn.LET(_xlpm._rowColumnNameHeader,ROW(_xlpm._columnNameHeader),_xlpm._startOfSheetExplanations,MATCH(_xlpm._thisSheet,_xlpm._readmeSheetsRange,0),_xlpm._numberOfEntriesForSheet,COUNTIF(_xlpm._readmeSheetsRange,_xlpm._thisSheet),_xlpm._searchRange,OFFSET(_xlpm._columnSearchHeader,_xlpm._startOfSheetExplanations-_xlpm._rowColumnNameHeader,0,_xlpm._numberOfEntriesForSheet,1),_xlpm._entryOffset,MATCH(_xlpm._columnName,_xlpm._searchRange,0)-1+_xlpm._startOfSheetExplanations,HYPERLINK("#'"&Helper!$G$2&"'!"&CHAR(CODE("A")+COLUMN(_xlpm._columnNameHeader)-1)&_xlpm._entryOffset,Definitions!$AY$4)))(Helper!$G$3,E$2,README!$E:$E,README!$I$36,README!$B$36)} -> ◈ | G1: {=_xlfn.LAMBDA(_xlpm._thisSheet,_xlpm._columnName,_xlpm._readmeSheetsRange,_xlpm._columnSearchHeader,_xlpm._columnNameHeader,_xlfn.LET(_xlpm._rowColumnNameHeader,ROW(_xlpm._columnNameHeader),_xlpm._startOfSheetExplanations,MATCH(_xlpm._thisSheet,_xlpm._readmeSheetsRange,0),_xlpm._numberOfEntriesForSheet,COUNTIF(_xlpm._readmeSheetsRange,_xlpm._thisSheet),_xlpm._searchRange,OFFSET(_xlpm._columnSearchHeader,_xlpm._startOfSheetExplanations-_xlpm._rowColumnNameHeader,0,_xlpm._numberOfEntriesForSheet,1),_xlpm._entryOffset,MATCH(_xlpm._columnName,_xlpm._searchRange,0)-1+_xlpm._startOfSheetExplanations,HYPERLINK("#'"&Helper!$G$2&"'!"&CHAR(CODE("A")+COLUMN(_xlpm._columnNameHeader)-1)&_xlpm._entryOffset,Definitions!$AY$4)))(Helper!$G$3,G$2,README!$E:$E,README!$I$36,README!$B$36)} -> ◈ | M1: {=_xlfn.LAMBDA(_xlpm._thisSheet,_xlpm._columnName,_xlpm._readmeSheetsRange,_xlpm._columnSearchHeader,_xlpm._columnNameHeader,_xlfn.LET(_xlpm._rowColumnNameHeader,ROW(_xlpm._columnNameHeader),_xlpm._startOfSheetExplanations,MATCH(_xlpm._thisSheet,_xlpm._readmeSheetsRange,0),_xlpm._numberOfEntriesForSheet,COUNTIF(_xlpm._readmeSheetsRange,_xlpm._thisSheet),_xlpm._searchRange,OFFSET(_xlpm._columnSearchHeader,_xlpm._startOfSheetExplanations-_xlpm._rowColumnNameHeader,0,_xlpm._numberOfEntriesForSheet,1),_xlpm._entryOffset,MATCH(_xlpm._columnName,_xlpm._searchRange,0)-1+_xlpm._startOfSheetExplanations,HYPERLINK("#'"&Helper!$G$2&"'!"&CHAR(CODE("A")+COLUMN(_xlpm._columnNameHeader)-1)&_xlpm._entryOffset,Definitions!$AY$4)))(Helper!$G$3,M$2,README!$E:$E,README!$I$36,README!$B$36)} -> ◈ | O1: {=_xlfn.LAMBDA(_xlpm._thisSheet,_xlpm._columnName,_xlpm._readmeSheetsRange,_xlpm._columnSearchHeader,_xlpm._columnNameHeader,_xlfn.LET(_xlpm._rowColumnNameHeader,ROW(_xlpm._columnNameHeader),_xlpm._startOfSheetExplanations,MATCH(_xlpm._thisSheet,_xlpm._readmeSheetsRange,0),_xlpm._numberOfEntriesForSheet,COUNTIF(_xlpm._readmeSheetsRange,_xlpm._thisSheet),_xlpm._searchRange,OFFSET(_xlpm._columnSearchHeader,_xlpm._startOfSheetExplanations-_xlpm._rowColumnNameHeader,0,_xlpm._numberOfEntriesForSheet,1),_xlpm._entryOffset,MATCH(_xlpm._columnName,_xlpm._searchRange,0)-1+_xlpm._startOfSheetExplanations,HYPERLINK("#'"&Helper!$G$2&"'!"&CHAR(CODE("A")+COLUMN(_xlpm._columnNameHeader)-1)&_xlpm._entryOffset,Definitions!$AY$4)))(Helper!$G$3,O$2,README!$E:$E,README!$I$36,README!$B$36)} -> ◈ | Q1: {=_xlfn.LAMBDA(_xlpm._thisSheet,_xlpm._columnName,_xlpm._readmeSheetsRange,_xlpm._columnSearchHeader,_xlpm._columnNameHeader,_xlfn.LET(_xlpm._rowColumnNameHeader,ROW(_xlpm._columnNameHeader),_xlpm._startOfSheetExplanations,MATCH(_xlpm._thisSheet,_xlpm._readmeSheetsRange,0),_xlpm._numberOfEntriesForSheet,COUNTIF(_xlpm._readmeSheetsRange,_xlpm._thisSheet),_xlpm._searchRange,OFFSET(_xlpm._columnSearchHeader,_xlpm._startOfSheetExplanations-_xlpm._rowColumnNameHeader,0,_xlpm._numberOfEntriesForSheet,1),_xlpm._entryOffset,MATCH(_xlpm._columnName,_xlpm._searchRange,0)-1+_xlpm._startOfSheetExplanations,HYPERLINK("#'"&Helper!$G$2&"'!"&CHAR(CODE("A")+COLUMN(_xlpm._columnNameHeader)-1)&_xlpm._entryOffset,Definitions!$AY$4)))(Helper!$G$3,Q$2,README!$E:$E,README!$I$36,README!$B$36)} -> ◈ | T1: {=_xlfn.LAMBDA(_xlpm._thisSheet,_xlpm._columnName,_xlpm._readmeSheetsRange,_xlpm._columnSearchHeader,_xlpm._columnNameHeader,_xlfn.LET(_xlpm._rowColumnNameHeader,ROW(_xlpm._columnNameHeader),_xlpm._startOfSheetExplanations,MATCH(_xlpm._thisSheet,_xlpm._readmeSheetsRange,0),_xlpm._numberOfEntriesForSheet,COUNTIF(_xlpm._readmeSheetsRange,_xlpm._thisSheet),_xlpm._searchRange,OFFSET(_xlpm._columnSearchHeader,_xlpm._startOfSheetExplanations-_xlpm._rowColumnNameHeader,0,_xlpm._numberOfEntriesForSheet,1),_xlpm._entryOffset,MATCH(_xlpm._columnName,_xlpm._searchRange,0)-1+_xlpm._startOfSheetExplanations,HYPERLINK("#'"&Helper!$G$2&"'!"&CHAR(CODE("A")+COLUMN(_xlpm._columnNameHeader)-1)&_xlpm._entryOffset,Definitions!$AY$4)))(Helper!$G$3,T$2,README!$E:$E,README!$I$36,README!$B$36)} -> ◈ | V1: {=_xlfn.LAMBDA(_xlpm._thisSheet,_xlpm._columnName,_xlpm._readmeSheetsRange,_xlpm._columnSearchHeader,_xlpm._columnNameHeader,_xlfn.LET(_xlpm._rowColumnNameHeader,ROW(_xlpm._columnNameHeader),_xlpm._startOfSheetExplanations,MATCH(_xlpm._thisSheet,_xlpm._readmeSheetsRange,0),_xlpm._numberOfEntriesForSheet,COUNTIF(_xlpm._readmeSheetsRange,_xlpm._thisSheet),_xlpm._searchRange,OFFSET(_xlpm._columnSearchHeader,_xlpm._startOfSheetExplanations-_xlpm._rowColumnNameHeader,0,_xlpm._numberOfEntriesForSheet,1),_xlpm._entryOffset,MATCH(_xlpm._columnName,_xlpm._searchRange,0)-1+_xlpm._startOfSheetExplanations,HYPERLINK("#'"&Helper!$G$2&"'!"&CHAR(CODE("A")+COLUMN(_xlpm._columnNameHeader)-1)&_xlpm._entryOffset,Definitions!$AY$4)))(Helper!$G$3,V$2,README!$E:$E,README!$I$36,README!$B$36)} -> ◈ | Y1: {=_xlfn.LAMBDA(_xlpm._thisSheet,_xlpm._columnName,_xlpm._readmeSheetsRange,_xlpm._columnSearchHeader,_xlpm._columnNameHeader,_xlfn.LET(_xlpm._rowColumnNameHeader,ROW(_xlpm._columnNameHeader),_xlpm._startOfSheetExplanations,MATCH(_xlpm._thisSheet,_xlpm._readmeSheetsRange,0),_xlpm._numberOfEntriesForSheet,COUNTIF(_xlpm._readmeSheetsRange,_xlpm._thisSheet),_xlpm._searchRange,OFFSET(_xlpm._columnSearchHeader,_xlpm._startOfSheetExplanations-_xlpm._rowColumnNameHeader,0,_xlpm._numberOfEntriesForSheet,1),_xlpm._entryOffset,MATCH(_xlpm._columnName,_xlpm._searchRange,0)-1+_xlpm._startOfSheetExplanations,HYPERLINK("#'"&Helper!$G$2&"'!"&CHAR(CODE("A")+COLUMN(_xlpm._columnNameHeader)-1)&_xlpm._entryOffset,Definitions!$AY$4)))(Helper!$G$3,Y$2,README!$E:$E,README!$I$36,README!$B$36)} -> ◈ | AE1: {=_xlfn.LAMBDA(_xlpm._thisSheet,_xlpm._columnName,_xlpm._readmeSheetsRange,_xlpm._columnSearchHeader,_xlpm._columnNameHeader,_xlfn.LET(_xlpm._rowColumnNameHeader,ROW(_xlpm._columnNameHeader),_xlpm._startOfSheetExplanations,MATCH(_xlpm._thisSheet,_xlpm._readmeSheetsRange,0),_xlpm._numberOfEntriesForSheet,COUNTIF(_xlpm._readmeSheetsRange,_xlpm._thisSheet),_xlpm._searchRange,OFFSET(_xlpm._columnSearchHeader,_xlpm._startOfSheetExplanations-_xlpm._rowColumnNameHeader,0,_xlpm._numberOfEntriesForSheet,1),_xlpm._entryOffset,MATCH(_xlpm._columnName,_xlpm._searchRange,0)-1+_xlpm._startOfSheetExplanations,HYPERLINK("#'"&Helper!$G$2&"'!"&CHAR(CODE("A")+COLUMN(_xlpm._columnNameHeader)-1)&_xlpm._entryOffset,Definitions!$AY$4)))(Helper!$G$3,AE$2,README!$E:$E,README!$I$36,README!$B$36)} -> ◈ | AH1: {=_xlfn.LAMBDA(_xlpm._thisSheet,_xlpm._columnName,_xlpm._readmeSheetsRange,_xlpm._columnSearchHeader,_xlpm._columnNameHeader,_xlfn.LET(_xlpm._rowColumnNameHeader,ROW(_xlpm._columnNameHeader),_xlpm._startOfSheetExplanations,MATCH(_xlpm._thisSheet,_xlpm._readmeSheetsRange,0),_xlpm._numberOfEntriesForSheet,COUNTIF(_xlpm._readmeSheetsRange,_xlpm._thisSheet),_xlpm._searchRange,OFFSET(_xlpm._columnSearchHeader,_xlpm._startOfSheetExplanations-_xlpm._rowColumnNameHeader,0,_xlpm._numberOfEntriesForSheet,1),_xlpm._entryOffset,MATCH(_xlpm._columnName,_xlpm._searchRange,0)-1+_xlpm._startOfSheetExplanations,HYPERLINK("#'"&Helper!$G$2&"'!"&CHAR(CODE("A")+COLUMN(_xlpm._columnNameHeader)-1)&_xlpm._entryOffset,Definitions!$AY$4)))(Helper!$G$3,AH$2,README!$E:$E,README!$I$36,README!$B$36)} -> ◈ | AO1: {=_xlfn.LAMBDA(_xlpm._thisSheet,_xlpm._columnName,_xlpm._readmeSheetsRange,_xlpm._columnSearchHeader,_xlpm._columnNameHeader,_xlfn.LET(_xlpm._rowColumnNameHeader,ROW(_xlpm._columnNameHeader),_xlpm._startOfSheetExplanations,MATCH(_xlpm._thisSheet,_xlpm._readmeSheetsRange,0),_xlpm._numberOfEntriesForSheet,COUNTIF(_xlpm._readmeSheetsRange,_xlpm._thisSheet),_xlpm._searchRange,OFFSET(_xlpm._columnSearchHeader,_xlpm._startOfSheetExplanations-_xlpm._rowColumnNameHeader,0,_xlpm._numberOfEntriesForSheet,1),_xlpm._entryOffset,MATCH(_xlpm._columnName,_xlpm._searchRange,0)-1+_xlpm._startOfSheetExplanations,HYPERLINK("#'"&Helper!$G$2&"'!"&CHAR(CODE("A")+COLUMN(_xlpm._columnNameHeader)-1)&_xlpm._entryOffset,Definitions!$AY$4)))(Helper!$G$3,AO$2,README!$E:$E,README!$I$36,README!$B$36)} -> ◈ | AQ1: {=_xlfn.LAMBDA(_xlpm._thisSheet,_xlpm._columnName,_xlpm._readmeSheetsRange,_xlpm._columnSearchHeader,_xlpm._columnNameHeader,_xlfn.LET(_xlpm._rowColumnNameHeader,ROW(_xlpm._columnNameHeader),_xlpm._startOfSheetExplanations,MATCH(_xlpm._thisSheet,_xlpm._readmeSheetsRange,0),_xlpm._numberOfEntriesForSheet,COUNTIF(_xlpm._readmeSheetsRange,_xlpm._thisSheet),_xlpm._searchRange,OFFSET(_xlpm._columnSearchHeader,_xlpm._startOfSheetExplanations-_xlpm._rowColumnNameHeader,0,_xlpm._numberOfEntriesForSheet,1),_xlpm._entryOffset,MATCH(_xlpm._columnName,_xlpm._searchRange,0)-1+_xlpm._startOfSheetExplanations,HYPERLINK("#'"&Helper!$G$2&"'!"&CHAR(CODE("A")+COLUMN(_xlpm._columnNameHeader)-1)&_xlpm._entryOffset,Definitions!$AY$4)))(Helper!$G$3,AQ$2,README!$E:$E,README!$I$36,README!$B$36)} -> ◈ | AU1: {=_xlfn.LAMBDA(_xlpm._thisSheet,_xlpm._columnName,_xlpm._readmeSheetsRange,_xlpm._columnSearchHeader,_xlpm._columnNameHeader,_xlfn.LET(_xlpm._rowColumnNameHeader,ROW(_xlpm._columnNameHeader),_xlpm._startOfSheetExplanations,MATCH(_xlpm._thisSheet,_xlpm._readmeSheetsRange,0),_xlpm._numberOfEntriesForSheet,COUNTIF(_xlpm._readmeSheetsRange,_xlpm._thisSheet),_xlpm._searchRange,OFFSET(_xlpm._columnSearchHeader,_xlpm._startOfSheetExplanations-_xlpm._rowColumnNameHeader,0,_xlpm._numberOfEntriesForSheet,1),_xlpm._entryOffset,MATCH(_xlpm._columnName,_xlpm._searchRange,0)-1+_xlpm._startOfSheetExplanations,HYPERLINK("#'"&Helper!$G$2&"'!"&CHAR(CODE("A")+COLUMN(_xlpm._columnNameHeader)-1)&_xlpm._entryOffset,Definitions!$AY$4)))(Helper!$G$3,AU$2,README!$E:$E,README!$I$36,README!$B$36)} -> ◈ | AW1: {=_xlfn.LAMBDA(_xlpm._thisSheet,_xlpm._columnName,_xlpm._readmeSheetsRange,_xlpm._columnSearchHeader,_xlpm._columnNameHeader,_xlfn.LET(_xlpm._rowColumnNameHeader,ROW(_xlpm._columnNameHeader),_xlpm._startOfSheetExplanations,MATCH(_xlpm._thisSheet,_xlpm._readmeSheetsRange,0),_xlpm._numberOfEntriesForSheet,COUNTIF(_xlpm._readmeSheetsRange,_xlpm._thisSheet),_xlpm._searchRange,OFFSET(_xlpm._columnSearchHeader,_xlpm._startOfSheetExplanations-_xlpm._rowColumnNameHeader,0,_xlpm._numberOfEntriesForSheet,1),_xlpm._entryOffset,MATCH(_xlpm._columnName,_xlpm._searchRange,0)-1+_xlpm._startOfSheetExplanations,HYPERLINK("#'"&Helper!$G$2&"'!"&CHAR(CODE("A")+COLUMN(_xlpm._columnNameHeader)-1)&_xlpm._entryOffset,Definitions!$AY$4)))(Helper!$G$3,AW$2,README!$E:$E,README!$I$36,README!$B$36)} -> ◈ | AY1: {=_xlfn.LAMBDA(_xlpm._thisSheet,_xlpm._columnName,_xlpm._readmeSheetsRange,_xlpm._columnSearchHeader,_xlpm._columnNameHeader,_xlfn.LET(_xlpm._rowColumnNameHeader,ROW(_xlpm._columnNameHeader),_xlpm._startOfSheetExplanations,MATCH(_xlpm._thisSheet,_xlpm._readmeSheetsRange,0),_xlpm._numberOfEntriesForSheet,COUNTIF(_xlpm._readmeSheetsRange,_xlpm._thisSheet),_xlpm._searchRange,OFFSET(_xlpm._columnSearchHeader,_xlpm._startOfSheetExplanations-_xlpm._rowColumnNameHeader,0,_xlpm._numberOfEntriesForSheet,1),_xlpm._entryOffset,MATCH(_xlpm._columnName,_xlpm._searchRange,0)-1+_xlpm._startOfSheetExplanations,HYPERLINK("#'"&Helper!$G$2&"'!"&CHAR(CODE("A")+COLUMN(_xlpm._columnNameHeader)-1)&_xlpm._entryOffset,Definitions!$AY$4)))(Helper!$G$3,AY$2,README!$E:$E,README!$I$36,README!$B$36)} -> ◈ | BA1: {=_xlfn.LAMBDA(_xlpm._thisSheet,_xlpm._columnName,_xlpm._readmeSheetsRange,_xlpm._columnSearchHeader,_xlpm._columnNameHeader,_xlfn.LET(_xlpm._rowColumnNameHeader,ROW(_xlpm._columnNameHeader),_xlpm._startOfSheetExplanations,MATCH(_xlpm._thisSheet,_xlpm._readmeSheetsRange,0),_xlpm._numberOfEntriesForSheet,COUNTIF(_xlpm._readmeSheetsRange,_xlpm._thisSheet),_xlpm._searchRange,OFFSET(_xlpm._columnSearchHeader,_xlpm._startOfSheetExplanations-_xlpm._rowColumnNameHeader,0,_xlpm._numberOfEntriesForSheet,1),_xlpm._entryOffset,MATCH(_xlpm._columnName,_xlpm._searchRange,0)-1+_xlpm._startOfSheetExplanations,HYPERLINK("#'"&Helper!$G$2&"'!"&CHAR(CODE("A")+COLUMN(_xlpm._columnNameHeader)-1)&_xlpm._entryOffset,Definitions!$AY$4)))(Helper!$G$3,BA$2,README!$E:$E,README!$I$36,README!$B$36)} -> ◈ | BF1: {=_xlfn.LAMBDA(_xlpm._thisSheet,_xlpm._columnName,_xlpm._readmeSheetsRange,_xlpm._columnSearchHeader,_xlpm._columnNameHeader,_xlfn.LET(_xlpm._rowColumnNameHeader,ROW(_xlpm._columnNameHeader),_xlpm._startOfSheetExplanations,MATCH(_xlpm._thisSheet,_xlpm._readmeSheetsRange,0),_xlpm._numberOfEntriesForSheet,COUNTIF(_xlpm._readmeSheetsRange,_xlpm._thisSheet),_xlpm._searchRange,OFFSET(_xlpm._columnSearchHeader,_xlpm._startOfSheetExplanations-_xlpm._rowColumnNameHeader,0,_xlpm._numberOfEntriesForSheet,1),_xlpm._entryOffset,MATCH(_xlpm._columnName,_xlpm._searchRange,0)-1+_xlpm._startOfSheetExplanations,HYPERLINK("#'"&Helper!$G$2&"'!"&CHAR(CODE("A")+COLUMN(_xlpm._columnNameHeader)-1)&_xlpm._entryOffset,Definitions!$AY$4)))(Helper!$G$3,BF$2,README!$E:$E,README!$I$36,README!$B$36)} -> ◈ | BI1: {=_xlfn.LAMBDA(_xlpm._thisSheet,_xlpm._columnName,_xlpm._readmeSheetsRange,_xlpm._columnSearchHeader,_xlpm._columnNameHeader,_xlfn.LET(_xlpm._rowColumnNameHeader,ROW(_xlpm._columnNameHeader),_xlpm._startOfSheetExplanations,MATCH(_xlpm._thisSheet,_xlpm._readmeSheetsRange,0),_xlpm._numberOfEntriesForSheet,COUNTIF(_xlpm._readmeSheetsRange,_xlpm._thisSheet),_xlpm._searchRange,OFFSET(_xlpm._columnSearchHeader,_xlpm._startOfSheetExplanations-_xlpm._rowColumnNameHeader,0,_xlpm._numberOfEntriesForSheet,1),_xlpm._entryOffset,MATCH(_xlpm._columnName,_xlpm._searchRange,0)-1+_xlpm._startOfSheetExplanations,HYPERLINK("#'"&Helper!$G$2&"'!"&CHAR(CODE("A")+COLUMN(_xlpm._columnNameHeader)-1)&_xlpm._entryOffset,Definitions!$AY$4)))(Helper!$G$3,BI$2,README!$E:$E,README!$I$36,README!$B$36)} -> ◈ | BK1: {=_xlfn.LAMBDA(_xlpm._thisSheet,_xlpm._columnName,_xlpm._readmeSheetsRange,_xlpm._columnSearchHeader,_xlpm._columnNameHeader,_xlfn.LET(_xlpm._rowColumnNameHeader,ROW(_xlpm._columnNameHeader),_xlpm._startOfSheetExplanations,MATCH(_xlpm._thisSheet,_xlpm._readmeSheetsRange,0),_xlpm._numberOfEntriesForSheet,COUNTIF(_xlpm._readmeSheetsRange,_xlpm._thisSheet),_xlpm._searchRange,OFFSET(_xlpm._columnSearchHeader,_xlpm._startOfSheetExplanations-_xlpm._rowColumnNameHeader,0,_xlpm._numberOfEntriesForSheet,1),_xlpm._entryOffset,MATCH(_xlpm._columnName,_xlpm._searchRange,0)-1+_xlpm._startOfSheetExplanations,HYPERLINK("#'"&Helper!$G$2&"'!"&CHAR(CODE("A")+COLUMN(_xlpm._columnNameHeader)-1)&_xlpm._entryOffset,Definitions!$AY$4)))(Helper!$G$3,BK$2,README!$E:$E,README!$I$36,README!$B$36)} -> ◈
A2: Yes / No | C2: Company Name | E2: Damage Categories | G2: Damage Criteria | M2: Risk Treatment | O2: Type of gateway | Q2: Damage Levels | T2: Line Width | V2: Required Attack Potential | Y2: Required Attack Potential - Factors | AE2: Risk Values | AH2: Risk Matrix | AO2: Stakeholders | AQ2: Additional assumptions / countermeasures | AU2: Display Blue Box | AW2: Product Life Time / Support Duration | AY2: Helper Link | BA2: JSON Export | BF2: Supply Chain Answers | BI2: Secure Production | BK2: Supply Chain Security
A3: Choices | C3: Name | E3: Name | G3: Category | H3: Name | I3: Description | J3: Damage Level | K3: Not first of Category | M3: Options | O3: Options | Q3: Name | R3: Value | T3: # Characters | V3: Threshold | W3: RAP | Y3: Class | Z3: Factor | AA3: Value | AB3: Class ID | AC3: Not first of Category | AE3: Name | AF3: Value | AH3: RAP > v Damage | AI3: =OFFSET($W$4,COLUMN()-COLUMN($AI$2),0) -> Basic | AJ3: =OFFSET($W$4,COLUMN()-COLUMN($AI$2),0) -> Enhanced-Basic | AK3: =OFFSET($W$4,COLUMN()-COLUMN($AI$2),0) -> Moderate | AL3: =OFFSET($W$4,COLUMN()-COLUMN($AI$2),0) -> High | AM3: =OFFSET($W$4,COLUMN()-COLUMN($AI$2),0) -> Beyond High | AO3: Stakeholder Names | AQ3: Element Type | AR3: Syntax Start | AS3: Syntax End | AU3: Marking for Comments at Answers that Trigger Assumptions / Countermeasures | AW3: Time frame | AY3: Symbol (not allowed in IDs) | BA3: Sheet Name | BB3: Columns | BC3: Shadow ID Column | BD3: Shadow ID Header | BF3: Answer | BG3: Explanation | BI3: Options | BK3: Options
A4: Yes | C4: acontis techonlogies GmbH | E4: Personal Data | G4: =$E$4 -> Personal Data | H4: Personal data (low) | I4: It is possible that the person affected will be negatively affected in his or her social status or economic situation | J4: Low | K4: =OFFSET($G4,-1,0)=$G4 -> FALSE | M4: Accept | O4: Local network gateway | Q4: Immaterial | R4: 1 | T4: 60 | V4: 0 | W4: Basic | Y4: Elapsed Time | Z4: <= one day | AA4: 0 | AB4: {=IF(ROW()=ROW($AB$3)+1,0,INDEX($AB:$AB,ROW()-1))+IF($Y4=INDEX($Y:$Y,ROW()-1),0,1)} -> 1 | AC4: =OFFSET($AB4,-1,0)=$AB4 -> FALSE | AE4: No Risk | AF4: 0 | AH4: =Q4 -> Immaterial | AI4: =$AE$5 -> Low | AJ4: =$AE$5 -> Low | AK4: =$AE$5 -> Low | AL4: =$AE$5 -> Low | AM4: =$AE$5 -> Low | AO4: =$C$4 -> acontis techonlogies GmbH | AQ4: Assumption | AR4: {A | AS4: } | AU4: Yes | AW4: 0 - 5 years | AY4: =_xlfn.UNICHAR(9672) -> ◈ | BA4: {=GetSheetName(Questionnaire!$L$3)} -> Questionnaire | BB4: {=GetColumnLetter(Questionnaire!$A$2)&GetColumnLetter(Questionnaire!$K$2)&GetColumnLetter(Questionnaire!$C$2)&GetColumnLetter(Questionnaire!$D$2)&GetColumnLetter(Questionnaire!$E$2)&GetColumnLetter(Questionnaire!$F$2)&GetColumnLetter(Questionnaire!$G$2)} -> AKCDEFG | BC4: {=GetColumnLetter(Questionnaire!$L$3)} -> L | BD4: =ROW(Questionnaire!$L$2) -> 2 | BF4: Yes | BG4: The suppliers are trustworthy | BI4: No protection | BK4: Established supplier (several years of positive cooperation, sufficient size) (Open source alternative: git with regular updates)
A5: No | E5: Loss of Intellectual Property | G5: =$E$4 -> Personal Data | H5: Personal data (significant) | I5: The person affected can be significantly impaired in his or her social status or economic circumstances | J5: High | K5: =OFFSET($G5,-1,0)=$G5 -> TRUE | M5: Avoid | O5: Internet-facing gateway | Q5: Low | R5: 2 | V5: 10 | W5: Enhanced-Basic | Y5: Elapsed Time | Z5: <= one week | AA5: 1 | AB5: {=IF(ROW()=ROW($AB$3)+1,0,INDEX($AB:$AB,ROW()-1))+IF($Y5=INDEX($Y:$Y,ROW()-1),0,1)} -> 1 | AC5: =OFFSET($AB5,-1,0)=$AB5 -> TRUE | AE5: Low | AF5: 1 | AH5: =Q5 -> Low | AI5: =$AE$7 -> High | AJ5: =$AE$6 -> Moderate | AK5: =$AE$6 -> Moderate | AL5: =$AE$6 -> Moderate | AM5: =$AE$5 -> Low | AO5: Customer | AQ5: Countermeasure | AR5: {C | AS5: } | AW5: 5 - 10 years | BA5: {=GetSheetName('Risk Treatment'!$U$4)} -> Risk Treatment | BB5: {=GetColumnLetter('Risk Treatment'!$C$4)&GetColumnLetter('Risk Treatment'!$F$4)&GetColumnLetter('Risk Treatment'!$H$4)&GetColumnLetter('Risk Treatment'!$I$4)&GetColumnLetter('Risk Treatment'!$J$4)&GetColumnLetter('Risk Treatment'!$O$4)&GetColumnLetter('Risk Treatment'!$R$4)} -> CFHIJOR | BC5: {=GetColumnLetter('Risk Treatment'!$U$4)} -> U | BD5: =ROW('Risk Treatment'!$U$4) -> 4 | BF5: No | BG5: At least one supplier is not trusted | BI5: Internal production - only access control | BK5: Renowned supplier (internationally well-known) (Open Source: large renowned project)
E6: Financial and Legal | G6: =$E$4 -> Personal Data | H6: Personal data (ruinous) | I6: The person affected can be ruinously impaired in his social status and economic circumstances. The freedom of the person concerned is threatened | J6: Critical | K6: =OFFSET($G6,-1,0)=$G6 -> TRUE | M6: Mitigate | Q6: Medium | R6: 3 | V6: 14 | W6: Moderate | Y6: Elapsed Time | Z6: <= one month | AA6: 4 | AB6: {=IF(ROW()=ROW($AB$3)+1,0,INDEX($AB:$AB,ROW()-1))+IF($Y6=INDEX($Y:$Y,ROW()-1),0,1)} -> 1 | AC6: =OFFSET($AB6,-1,0)=$AB6 -> TRUE | AE6: Moderate | AF6: 2 | AH6: =Q6 -> Medium | AI6: =$AE$8 -> Very High | AJ6: =$AE$7 -> High | AK6: =$AE$7 -> High | AL6: =$AE$6 -> Moderate | AM6: =$AE$6 -> Moderate | AO6: Other (see comment) | AQ6: RAP Delimiter (Mitigation sheet only) | AR6: : | AW6: 10 - 20 years | BA6: {=GetSheetName('Result Summary'!$I$17)} -> Result Summary | BB6: {=GetColumnLetter('Result Summary'!$A$17)&GetColumnLetter('Result Summary'!$B$17)&GetColumnLetter('Result Summary'!$C$17)} -> ABC | BC6: {=GetColumnLetter('Result Summary'!$I$17)} -> I | BD6: =ROW('Result Summary'!$I$17) -> 17 | BF6: N/A | BG6: Not applicable: no supplier | BI6: Internal production according to IT requirements | BK6: Supplier agreed to cybersecurity requirements in a contract (Open source alternative: Foundation / open source steward)
E7: Safety | G7: =$E$5 -> Loss of Intellectual Property | H7: IP (slightly innovative) | I7: Loss of general idea how product works or low impact on markets (little innovation / very small market) | J7: Low | K7: =OFFSET($G7,-1,0)=$G7 -> FALSE | M7: Transfer | Q7: High | R7: 4 | V7: 20 | W7: High | Y7: Elapsed Time | Z7: <= six months | AA7: 10 | AB7: {=IF(ROW()=ROW($AB$3)+1,0,INDEX($AB:$AB,ROW()-1))+IF($Y7=INDEX($Y:$Y,ROW()-1),0,1)} -> 1 | AC7: =OFFSET($AB7,-1,0)=$AB7 -> TRUE | AE7: High | AF7: 3 | AH7: =Q7 -> High | AI7: =$AE$8 -> Very High | AJ7: =$AE$8 -> Very High | AK7: =$AE$7 -> High | AL7: =$AE$7 -> High | AM7: =$AE$6 -> Moderate | AW7: 20+ years | BI7: Internal validated production (e.g., ISACA OT-Check) | BK7: Supplier is audited (by the Q-department)
E8: Function and Availability | G8: =$E$5 -> Loss of Intellectual Property | H8: IP (moderately innovative) | I8: Relevant aspects of system is comprehensible or moderate impact on markets (some innovation in the product / medium size market) | J8: Medium | K8: =OFFSET($G8,-1,0)=$G8 -> TRUE | Q8: Critical | R8: 5 | V8: 25 | W8: Beyond High | Y8: Elapsed Time | Z8: Years | AA8: 19 | AB8: {=IF(ROW()=ROW($AB$3)+1,0,INDEX($AB:$AB,ROW()-1))+IF($Y8=INDEX($Y:$Y,ROW()-1),0,1)} -> 1 | AC8: =OFFSET($AB8,-1,0)=$AB8 -> TRUE | AE8: Very High | AF8: 4 | AH8: =Q8 -> Critical | AI8: =$AE$8 -> Very High | AJ8: =$AE$8 -> Very High | AK8: =$AE$8 -> Very High | AL8: =$AE$7 -> High | AM8: =$AE$6 -> Moderate | BI8: Certified production (e.g., IEC 62443) | BK8: Supplier is certified
G9: =$E$5 -> Loss of Intellectual Property | H9: IP (highly innovative) | I9: Can be copied / technology available or high impact on markets (highly innovative product / high-volume market) | J9: High | K9: =OFFSET($G9,-1,0)=$G9 -> TRUE | Y9: Elapsed Time | Z9: Decades | AA9: 25 | AB9: {=IF(ROW()=ROW($AB$3)+1,0,INDEX($AB:$AB,ROW()-1))+IF($Y9=INDEX($Y:$Y,ROW()-1),0,1)} -> 1 | AC9: =OFFSET($AB9,-1,0)=$AB9 -> TRUE | BI9: Software: CI/CD Pipeline
G10: =$E$6 -> Financial and Legal | H10: Low financial damage | I10: Direct loss, fines for infringements of laws, or violations of contracts (low volume) | J10: Low | K10: =OFFSET($G10,-1,0)=$G10 -> FALSE | Y10: Expertise | Z10: Layman | AA10: 0 | AB10: {=IF(ROW()=ROW($AB$3)+1,0,INDEX($AB:$AB,ROW()-1))+IF($Y10=INDEX($Y:$Y,ROW()-1),0,1)} -> 2 | AC10: =OFFSET($AB10,-1,0)=$AB10 -> FALSE | BI10: Software: Internal Audit
G11: =$E$6 -> Financial and Legal | H11: Medium financial damage | I11: Direct loss, fines for infringements of laws, or violations of contracts (medium volume) | J11: Medium | K11: =OFFSET($G11,-1,0)=$G11 -> TRUE | Y11: Expertise | Z11: Proficient | AA11: 3 | AB11: {=IF(ROW()=ROW($AB$3)+1,0,INDEX($AB:$AB,ROW()-1))+IF($Y11=INDEX($Y:$Y,ROW()-1),0,1)} -> 2 | AC11: =OFFSET($AB11,-1,0)=$AB11 -> TRUE | BI11: Software: ISO-certified
G12: =$E$6 -> Financial and Legal | H12: High financial damage | I12: Direct loss, fines for infringements of laws, or violations of contracts (high volume) | J12: High | K12: =OFFSET($G12,-1,0)=$G12 -> TRUE | Y12: Expertise | Z12: Expert | AA12: 6 | AB12: {=IF(ROW()=ROW($AB$3)+1,0,INDEX($AB:$AB,ROW()-1))+IF($Y12=INDEX($Y:$Y,ROW()-1),0,1)} -> 2 | AC12: =OFFSET($AB12,-1,0)=$AB12 -> TRUE
G13: =$E$6 -> Financial and Legal | H13: Critical financial damage | I13: Loss of freedom for employees, direct loss, fines for infringements of laws, or violations of contracts (critical volume) | J13: Critical | K13: =OFFSET($G13,-1,0)=$G13 -> TRUE | Y13: Expertise | Z13: Multiple experts | AA13: 8 | AB13: {=IF(ROW()=ROW($AB$3)+1,0,INDEX($AB:$AB,ROW()-1))+IF($Y13=INDEX($Y:$Y,ROW()-1),0,1)} -> 2 | AC13: =OFFSET($AB13,-1,0)=$AB13 -> TRUE
G14: =$E$7 -> Safety | H14: Potentially dangerous situation | I14: Potentially dangerous situation | J14: Low | K14: =OFFSET($G14,-1,0)=$G14 -> FALSE | Y14: Knowledge of TOE | Z14: Public | AA14: 0 | AB14: {=IF(ROW()=ROW($AB$3)+1,0,INDEX($AB:$AB,ROW()-1))+IF($Y14=INDEX($Y:$Y,ROW()-1),0,1)} -> 3 | AC14: =OFFSET($AB14,-1,0)=$AB14 -> FALSE
G15: =$E$7 -> Safety | H15: Light or moderate injury | I15: Light or moderate injury | J15: Medium | K15: =OFFSET($G15,-1,0)=$G15 -> TRUE | Y15: Knowledge of TOE | Z15: Restricted | AA15: 3 | AB15: {=IF(ROW()=ROW($AB$3)+1,0,INDEX($AB:$AB,ROW()-1))+IF($Y15=INDEX($Y:$Y,ROW()-1),0,1)} -> 3 | AC15: =OFFSET($AB15,-1,0)=$AB15 -> TRUE
G16: =$E$7 -> Safety | H16: Severe injury (survival probable) | I16: Severe injury (survival probable) | J16: High | K16: =OFFSET($G16,-1,0)=$G16 -> TRUE | Y16: Knowledge of TOE | Z16: Sensitive | AA16: 7 | AB16: {=IF(ROW()=ROW($AB$3)+1,0,INDEX($AB:$AB,ROW()-1))+IF($Y16=INDEX($Y:$Y,ROW()-1),0,1)} -> 3 | AC16: =OFFSET($AB16,-1,0)=$AB16 -> TRUE
G17: =$E$7 -> Safety | H17: Life-threatening injury | I17: Life-threatening injury | J17: Critical | K17: =OFFSET($G17,-1,0)=$G17 -> TRUE | Y17: Knowledge of TOE | Z17: Critical | AA17: 11 | AB17: {=IF(ROW()=ROW($AB$3)+1,0,INDEX($AB:$AB,ROW()-1))+IF($Y17=INDEX($Y:$Y,ROW()-1),0,1)} -> 3 | AC17: =OFFSET($AB17,-1,0)=$AB17 -> TRUE
G18: =$E$8 -> Function and Availability | H18: Disturbance | I18: Minor disturbance, customer can quickly fix issue himself (e.g. reset) | J18: Low | K18: =OFFSET($G18,-1,0)=$G18 -> FALSE | Y18: Window of Opportunity | Z18: Unnecessary / unlimited access | AA18: 0 | AB18: {=IF(ROW()=ROW($AB$3)+1,0,INDEX($AB:$AB,ROW()-1))+IF($Y18=INDEX($Y:$Y,ROW()-1),0,1)} -> 4 | AC18: =OFFSET($AB18,-1,0)=$AB18 -> FALSE
G19: =$E$8 -> Function and Availability | H19: Service required | I19: Disturbance of function, service required | J19: Medium | K19: =OFFSET($G19,-1,0)=$G19 -> TRUE | Y19: Window of Opportunity | Z19: Easy | AA19: 1 | AB19: {=IF(ROW()=ROW($AB$3)+1,0,INDEX($AB:$AB,ROW()-1))+IF($Y19=INDEX($Y:$Y,ROW()-1),0,1)} -> 4 | AC19: =OFFSET($AB19,-1,0)=$AB19 -> TRUE
G20: =$E$8 -> Function and Availability | H20: Major disturbance | I20: Major disturbance of function | J20: High | K20: =OFFSET($G20,-1,0)=$G20 -> TRUE | Y20: Window of Opportunity | Z20: Moderate | AA20: 4 | AB20: {=IF(ROW()=ROW($AB$3)+1,0,INDEX($AB:$AB,ROW()-1))+IF($Y20=INDEX($Y:$Y,ROW()-1),0,1)} -> 4 | AC20: =OFFSET($AB20,-1,0)=$AB20 -> TRUE
G21: =$E$8 -> Function and Availability | H21: Environmental damage | I21: Singular incident with limited environmental damage | J21: High | K21: =OFFSET($G21,-1,0)=$G21 -> TRUE | Y21: Window of Opportunity | Z21: Difficult | AA21: 10 | AB21: {=IF(ROW()=ROW($AB$3)+1,0,INDEX($AB:$AB,ROW()-1))+IF($Y21=INDEX($Y:$Y,ROW()-1),0,1)} -> 4 | AC21: =OFFSET($AB21,-1,0)=$AB21 -> TRUE
G22: =$E$8 -> Function and Availability | H22: Critical disturbance (destruction) | I22: Destruction of plant, severe damage to assets or operational environment, critical disturbance of function | J22: Critical | K22: =OFFSET($G22,-1,0)=$G22 -> TRUE | Y22: Window of Opportunity | Z22: None | AA22: 25 | AB22: {=IF(ROW()=ROW($AB$3)+1,0,INDEX($AB:$AB,ROW()-1))+IF($Y22=INDEX($Y:$Y,ROW()-1),0,1)} -> 4 | AC22: =OFFSET($AB22,-1,0)=$AB22 -> TRUE
G23: =$E$8 -> Function and Availability | H23: Critical environmental damage | I23: Environmental damages that accumulate to critical impact over time as well as critical damages that happen in a single incident | J23: Critical | K23: =OFFSET($G23,-1,0)=$G23 -> TRUE | Y23: Equipment | Z23: Standard | AA23: 0 | AB23: {=IF(ROW()=ROW($AB$3)+1,0,INDEX($AB:$AB,ROW()-1))+IF($Y23=INDEX($Y:$Y,ROW()-1),0,1)} -> 5 | AC23: =OFFSET($AB23,-1,0)=$AB23 -> FALSE
Y24: Equipment | Z24: Specialized | AA24: 4 | AB24: {=IF(ROW()=ROW($AB$3)+1,0,INDEX($AB:$AB,ROW()-1))+IF($Y24=INDEX($Y:$Y,ROW()-1),0,1)} -> 5 | AC24: =OFFSET($AB24,-1,0)=$AB24 -> TRUE
Y25: Equipment | Z25: Bespoke | AA25: 7 | AB25: {=IF(ROW()=ROW($AB$3)+1,0,INDEX($AB:$AB,ROW()-1))+IF($Y25=INDEX($Y:$Y,ROW()-1),0,1)} -> 5 | AC25: =OFFSET($AB25,-1,0)=$AB25 -> TRUE
Y26: Equipment | Z26: Multiple bespoke | AA26: 9 | AB26: {=IF(ROW()=ROW($AB$3)+1,0,INDEX($AB:$AB,ROW()-1))+IF($Y26=INDEX($Y:$Y,ROW()-1),0,1)} -> 5 | AC26: =OFFSET($AB26,-1,0)=$AB26 -> TRUE

Sheet Questions
A1: {=_xlfn.LAMBDA(_xlpm._thisSheet,_xlpm._columnName,_xlpm._readmeSheetsRange,_xlpm._columnSearchHeader,_xlpm._columnNameHeader,_xlfn.LET(_xlpm._rowColumnNameHeader,ROW(_xlpm._columnNameHeader),_xlpm._startOfSheetExplanations,MATCH(_xlpm._thisSheet,_xlpm._readmeSheetsRange,0),_xlpm._numberOfEntriesForSheet,COUNTIF(_xlpm._readmeSheetsRange,_xlpm._thisSheet),_xlpm._searchRange,OFFSET(_xlpm._columnSearchHeader,_xlpm._startOfSheetExplanations-_xlpm._rowColumnNameHeader,0,_xlpm._numberOfEntriesForSheet,1),_xlpm._entryOffset,MATCH(_xlpm._columnName,_xlpm._searchRange,0)-1+_xlpm._startOfSheetExplanations,HYPERLINK("#'"&Helper!$G$2&"'!"&CHAR(CODE("A")+COLUMN(_xlpm._columnNameHeader)-1)&_xlpm._entryOffset,Definitions!$AY$4)))(Helper!$G$4,A$3,README!$E:$E,README!$I$36,README!$B$36)} -> ◈ | B1: {=_xlfn.LAMBDA(_xlpm._thisSheet,_xlpm._columnName,_xlpm._readmeSheetsRange,_xlpm._columnSearchHeader,_xlpm._columnNameHeader,_xlfn.LET(_xlpm._rowColumnNameHeader,ROW(_xlpm._columnNameHeader),_xlpm._startOfSheetExplanations,MATCH(_xlpm._thisSheet,_xlpm._readmeSheetsRange,0),_xlpm._numberOfEntriesForSheet,COUNTIF(_xlpm._readmeSheetsRange,_xlpm._thisSheet),_xlpm._searchRange,OFFSET(_xlpm._columnSearchHeader,_xlpm._startOfSheetExplanations-_xlpm._rowColumnNameHeader,0,_xlpm._numberOfEntriesForSheet,1),_xlpm._entryOffset,MATCH(_xlpm._columnName,_xlpm._searchRange,0)-1+_xlpm._startOfSheetExplanations,HYPERLINK("#'"&Helper!$G$2&"'!"&CHAR(CODE("A")+COLUMN(_xlpm._columnNameHeader)-1)&_xlpm._entryOffset,Definitions!$AY$4)))(Helper!$G$4,B$3,README!$E:$E,README!$I$36,README!$B$36)} -> ◈ | C1: {=_xlfn.LAMBDA(_xlpm._thisSheet,_xlpm._columnName,_xlpm._readmeSheetsRange,_xlpm._columnSearchHeader,_xlpm._columnNameHeader,_xlfn.LET(_xlpm._rowColumnNameHeader,ROW(_xlpm._columnNameHeader),_xlpm._startOfSheetExplanations,MATCH(_xlpm._thisSheet,_xlpm._readmeSheetsRange,0),_xlpm._numberOfEntriesForSheet,COUNTIF(_xlpm._readmeSheetsRange,_xlpm._thisSheet),_xlpm._searchRange,OFFSET(_xlpm._columnSearchHeader,_xlpm._startOfSheetExplanations-_xlpm._rowColumnNameHeader,0,_xlpm._numberOfEntriesForSheet,1),_xlpm._entryOffset,MATCH(_xlpm._columnName,_xlpm._searchRange,0)-1+_xlpm._startOfSheetExplanations,HYPERLINK("#'"&Helper!$G$2&"'!"&CHAR(CODE("A")+COLUMN(_xlpm._columnNameHeader)-1)&_xlpm._entryOffset,Definitions!$AY$4)))(Helper!$G$4,C$3,README!$E:$E,README!$I$36,README!$B$36)} -> ◈ | D1: {=_xlfn.LAMBDA(_xlpm._thisSheet,_xlpm._columnName,_xlpm._readmeSheetsRange,_xlpm._columnSearchHeader,_xlpm._columnNameHeader,_xlfn.LET(_xlpm._rowColumnNameHeader,ROW(_xlpm._columnNameHeader),_xlpm._startOfSheetExplanations,MATCH(_xlpm._thisSheet,_xlpm._readmeSheetsRange,0),_xlpm._numberOfEntriesForSheet,COUNTIF(_xlpm._readmeSheetsRange,_xlpm._thisSheet),_xlpm._searchRange,OFFSET(_xlpm._columnSearchHeader,_xlpm._startOfSheetExplanations-_xlpm._rowColumnNameHeader,0,_xlpm._numberOfEntriesForSheet,1),_xlpm._entryOffset,MATCH(_xlpm._columnName,_xlpm._searchRange,0)-1+_xlpm._startOfSheetExplanations,HYPERLINK("#'"&Helper!$G$2&"'!"&CHAR(CODE("A")+COLUMN(_xlpm._columnNameHeader)-1)&_xlpm._entryOffset,Definitions!$AY$4)))(Helper!$G$4,D$3,README!$E:$E,README!$I$36,README!$B$36)} -> ◈ | E1: {=_xlfn.LAMBDA(_xlpm._thisSheet,_xlpm._columnName,_xlpm._readmeSheetsRange,_xlpm._columnSearchHeader,_xlpm._columnNameHeader,_xlfn.LET(_xlpm._rowColumnNameHeader,ROW(_xlpm._columnNameHeader),_xlpm._startOfSheetExplanations,MATCH(_xlpm._thisSheet,_xlpm._readmeSheetsRange,0),_xlpm._numberOfEntriesForSheet,COUNTIF(_xlpm._readmeSheetsRange,_xlpm._thisSheet),_xlpm._searchRange,OFFSET(_xlpm._columnSearchHeader,_xlpm._startOfSheetExplanations-_xlpm._rowColumnNameHeader,0,_xlpm._numberOfEntriesForSheet,1),_xlpm._entryOffset,MATCH(_xlpm._columnName,_xlpm._searchRange,0)-1+_xlpm._startOfSheetExplanations,HYPERLINK("#'"&Helper!$G$2&"'!"&CHAR(CODE("A")+COLUMN(_xlpm._columnNameHeader)-1)&_xlpm._entryOffset,Definitions!$AY$4)))(Helper!$G$4,E$3,README!$E:$E,README!$I$36,README!$B$36)} -> ◈ | F1: {=_xlfn.LAMBDA(_xlpm._thisSheet,_xlpm._columnName,_xlpm._readmeSheetsRange,_xlpm._columnSearchHeader,_xlpm._columnNameHeader,_xlfn.LET(_xlpm._rowColumnNameHeader,ROW(_xlpm._columnNameHeader),_xlpm._startOfSheetExplanations,MATCH(_xlpm._thisSheet,_xlpm._readmeSheetsRange,0),_xlpm._numberOfEntriesForSheet,COUNTIF(_xlpm._readmeSheetsRange,_xlpm._thisSheet),_xlpm._searchRange,OFFSET(_xlpm._columnSearchHeader,_xlpm._startOfSheetExplanations-_xlpm._rowColumnNameHeader,0,_xlpm._numberOfEntriesForSheet,1),_xlpm._entryOffset,MATCH(_xlpm._columnName,_xlpm._searchRange,0)-1+_xlpm._startOfSheetExplanations,HYPERLINK("#'"&Helper!$G$2&"'!"&CHAR(CODE("A")+COLUMN(_xlpm._columnNameHeader)-1)&_xlpm._entryOffset,Definitions!$AY$4)))(Helper!$G$4,F$3,README!$E:$E,README!$I$36,README!$B$36)} -> ◈ | G1: {=_xlfn.LAMBDA(_xlpm._thisSheet,_xlpm._columnName,_xlpm._readmeSheetsRange,_xlpm._columnSearchHeader,_xlpm._columnNameHeader,_xlfn.LET(_xlpm._rowColumnNameHeader,ROW(_xlpm._columnNameHeader),_xlpm._startOfSheetExplanations,MATCH(_xlpm._thisSheet,_xlpm._readmeSheetsRange,0),_xlpm._numberOfEntriesForSheet,COUNTIF(_xlpm._readmeSheetsRange,_xlpm._thisSheet),_xlpm._searchRange,OFFSET(_xlpm._columnSearchHeader,_xlpm._startOfSheetExplanations-_xlpm._rowColumnNameHeader,0,_xlpm._numberOfEntriesForSheet,1),_xlpm._entryOffset,MATCH(_xlpm._columnName,_xlpm._searchRange,0)-1+_xlpm._startOfSheetExplanations,HYPERLINK("#'"&Helper!$G$2&"'!"&CHAR(CODE("A")+COLUMN(_xlpm._columnNameHeader)-1)&_xlpm._entryOffset,Definitions!$AY$4)))(Helper!$G$4,G$3,README!$E:$E,README!$I$36,README!$B$36)} -> ◈ | H1: {=_xlfn.LAMBDA(_xlpm._thisSheet,_xlpm._columnName,_xlpm._readmeSheetsRange,_xlpm._columnSearchHeader,_xlpm._columnNameHeader,_xlfn.LET(_xlpm._rowColumnNameHeader,ROW(_xlpm._columnNameHeader),_xlpm._startOfSheetExplanations,MATCH(_xlpm._thisSheet,_xlpm._readmeSheetsRange,0),_xlpm._numberOfEntriesForSheet,COUNTIF(_xlpm._readmeSheetsRange,_xlpm._thisSheet),_xlpm._searchRange,OFFSET(_xlpm._columnSearchHeader,_xlpm._startOfSheetExplanations-_xlpm._rowColumnNameHeader,0,_xlpm._numberOfEntriesForSheet,1),_xlpm._entryOffset,MATCH(_xlpm._columnName,_xlpm._searchRange,0)-1+_xlpm._startOfSheetExplanations,HYPERLINK("#'"&Helper!$G$2&"'!"&CHAR(CODE("A")+COLUMN(_xlpm._columnNameHeader)-1)&_xlpm._entryOffset,Definitions!$AY$4)))(Helper!$G$4,H$3,README!$E:$E,README!$I$36,README!$B$36)} -> ◈ | ... N1: {=_xlfn.LAMBDA(_xlpm._thisSheet,_xlpm._columnName,_xlpm._readmeSheetsRange,_xlpm._columnSearchHeader,_xlpm._columnNameHeader,_xlfn.LET(_xlpm._rowColumnNameHeader,ROW(_xlpm._columnNameHeader),_xlpm._startOfSheetExplanations,MATCH(_xlpm._thisSheet,_xlpm._readmeSheetsRange,0),_xlpm._numberOfEntriesForSheet,COUNTIF(_xlpm._readmeSheetsRange,_xlpm._thisSheet),_xlpm._searchRange,OFFSET(_xlpm._columnSearchHeader,_xlpm._startOfSheetExplanations-_xlpm._rowColumnNameHeader,0,_xlpm._numberOfEntriesForSheet,1),_xlpm._entryOffset,MATCH(_xlpm._columnName,_xlpm._searchRange,0)-1+_xlpm._startOfSheetExplanations,HYPERLINK("#'"&Helper!$G$2&"'!"&CHAR(CODE("A")+COLUMN(_xlpm._columnNameHeader)-1)&_xlpm._entryOffset,Definitions!$AY$4)))(Helper!$G$4,N$3,README!$E:$E,README!$I$36,README!$B$36)} -> ◈
E2: First Answer | I2: Second Answer
A3: ID | B3: Text | C3: Indentation | D3: Is a Question | E3: Options Range Header | F3: Height | G3: Resulting Options | H3: Info Text | I3: Options Range Header | J3: Height | K3: Resulting Options | L3: Info Text | M3: Inactive On | N3: Comment | O3: Shadow ID | P3: Task ID | Q3: Is Inactive | R3: Question Shadow ID
