Workbook

Sheet Info
A1: Company name: | B1: acontis technology GmbH
A2: Product name: | B2: EC-Master stack
A3: Template revision: | B3: 3
A4: Comments:
A5: Info: | B5: Goal of the risk assessments is to identify potential damage or harm in the sense of a failure mode and effects analysis (FMEA) (safety) but also in the sense of the Cyber Resiliance Act (CRA) (security). In most cases, a chain of errors and/or circumstances leads to disaster. That is why it is important to consider this chain of events in preventive analysis. This also helps immensely in finding countermeasures and mitigations, as the chain can be broken at various points.

Sheet RiskAssessment
A1: Risk | N1: Analysis | R1: Counter measure/Mitigation | T1: Action | Z1: RiskMatrixData
A2: RID | B2: Title | C2: Description | D2: Create Date | E2: AS1 | F2: AS2 | G2: AS3 | H2: FAS | I2: Attack/Risk Path short | J2: Attack/Risk Path (ARP) | K2: =DamageCategory!$A$1 -> Damage Category | L2: Stakeholder | M2: Tags | N2: =Likelihood!$A$1 -> Likelihood | O2: =Impact!$A$1 -> Impact | P2: RPN | Q2: =RPN!$C$1 -> RPN Cat. | R2: Title | S2: Description | T2: Actions | U2: Issues | V2: Status | W2: =Owner!$A$1 -> Owner | X2: Start Date | Y2: Due Date | Z2: L | AA2: =RPN!$C$2 -> Low | AB2: =RPN!$C$3 -> Medium | AC2: =RPN!$C$4 -> High
A3: 1 | B3: =I3 -> AS1 -> AS3 | C3: Attacker has access to device/hardware the EC-Master is built-in: Keyboard, HDD, Network Adapter and uses a bug (infinite loop, race condition, memory leaks, out-of-memory, lock-up, crash) in the EC-Master. | D3: 46077 | E3: AS1 | F3: AS3 | H3: =IF(ISBLANK(E3),"s. D.",IF(ISBLANK(F3),E3,IF(ISBLANK(G3),F3,G3))) -> AS3 | I3: =IF(NOT(ISBLANK(E3)),E3,"")&IF(NOT(ISBLANK(F3))," -> "&F3,"")&IF(NOT(ISBLANK(G3))," -> "&G3,"") -> AS1 -> AS3 | J3: =I3&IF(NOT(ISBLANK(E3)),CHAR(10)&VLOOKUP(E3,AttackRiskStep!$A$3:$C$99,3,FALSE),"see Description")&IF(NOT(ISBLANK(F3))," -> "&CHAR(10)&VLOOKUP(F3,AttackRiskStep!$A$3:$C$99,3,FALSE),"")&IF(NOT(ISBLANK(G3))," -> "&CHAR(10)&VLOOKUP(G3,AttackRiskStep!$A$3:$C$99,3,FALSE),"") -> AS1 -> AS3 Gain access to a trusted operational environment -> Compromising the EC-Master stack using a software vulnerability | K3: Safety and Security | L3: acontis | N3: Unlikely | O3: Catastrophic | P3: =VLOOKUP($N3,Likelihood!$A$3:$B$7,2,FALSE)*VLOOKUP($O3,Impact!$A$4:$B$8,2,FALSE) -> 10 | Q3: =VLOOKUP(P3,RPN!$B$6:$C$22,2) -> Medium | R3: =$R$27 -> RID25: SW Tests | S3: =$S$27 -> RID25: Virus scan, Static code analysis (Lint, CppCheck), Unit Tests, Functional Tests, Dynamic Tests | T3: Help entry: Customer must ensure that nobody tampers with the files we deliver | Z3: =VLOOKUP($N3,Likelihood!$A$3:$C$7,2,FALSE)+RANDBETWEEN(-20,20)/100 -> 1.85 | AA3: =IF($Q3=AA$2,VLOOKUP($O3,Impact!$A$4:$B$8,2,FALSE)+RANDBETWEEN(-20,20)/100,NA()) -> #N/A | AB3: =IF($Q3=AB$2,VLOOKUP($O3,Impact!$A$4:$B$8,2,FALSE)+RANDBETWEEN(-20,20)/100,NA()) -> 4.87 | AC3: =IF($Q3=AC$2,VLOOKUP($O3,Impact!$A$4:$B$8,2,FALSE)+RANDBETWEEN(-20,20)/100,NA()) -> #N/A
A4: 2 | B4: =I4 -> AS2 -> AS3 | D4: 46077 | E4: AS2 | F4: AS3 | H4: =IF(ISBLANK(E4),"s. D.",IF(ISBLANK(F4),E4,IF(ISBLANK(G4),F4,G4))) -> AS3 | I4: =IF(NOT(ISBLANK(E4)),E4,"")&IF(NOT(ISBLANK(F4))," -> "&F4,"")&IF(NOT(ISBLANK(G4))," -> "&G4,"") -> AS2 -> AS3 | J4: =I4&IF(NOT(ISBLANK(E4)),CHAR(10)&VLOOKUP(E4,AttackRiskStep!$A$3:$C$99,3,FALSE),"see Description")&IF(NOT(ISBLANK(F4))," -> "&CHAR(10)&VLOOKUP(F4,AttackRiskStep!$A$3:$C$99,3,FALSE),"")&IF(NOT(ISBLANK(G4))," -> "&CHAR(10)&VLOOKUP(G4,AttackRiskStep!$A$3:$C$99,3,FALSE),"") -> AS2 -> AS3 Gain access to a local network -> Compromising the EC-Master stack using a software vulnerability | K4: Safety and Security | L4: acontis | N4: Unlikely | O4: Catastrophic | P4: =VLOOKUP($N4,Likelihood!$A$3:$B$7,2,FALSE)*VLOOKUP($O4,Impact!$A$4:$B$8,2,FALSE) -> 10 | Q4: =VLOOKUP(P4,RPN!$B$6:$C$22,2) -> Medium | R4: =$R$27 -> RID25: SW Tests | S4: =$S$27 -> RID25: Virus scan, Static code analysis (Lint, CppCheck), Unit Tests, Functional Tests, Dynamic Tests | T4: Help entry: Customer must ensure that nobody tampers with the files we deliver (e.g. with a firewall) | Z4: =VLOOKUP($N4,Likelihood!$A$3:$C$7,2,FALSE)+RANDBETWEEN(-20,20)/100 -> 2.16 | AA4: =IF($Q4=AA$2,VLOOKUP($O4,Impact!$A$4:$B$8,2,FALSE)+RANDBETWEEN(-20,20)/100,NA()) -> #N/A | AB4: =IF($Q4=AB$2,VLOOKUP($O4,Impact!$A$4:$B$8,2,FALSE)+RANDBETWEEN(-20,20)/100,NA()) -> 4.91 | AC4: =IF($Q4=AC$2,VLOOKUP($O4,Impact!$A$4:$B$8,2,FALSE)+RANDBETWEEN(-20,20)/100,NA()) -> #N/A
A5: 3 | B5: =I5 -> AS1 -> AS4 | D5: 46077 | E5: AS1 | F5: AS4 | H5: =IF(ISBLANK(E5),"s. D.",IF(ISBLANK(F5),E5,IF(ISBLANK(G5),F5,G5))) -> AS4 | I5: =IF(NOT(ISBLANK(E5)),E5,"")&IF(NOT(ISBLANK(F5))," -> "&F5,"")&IF(NOT(ISBLANK(G5))," -> "&G5,"") -> AS1 -> AS4 | J5: =I5&IF(NOT(ISBLANK(E5)),CHAR(10)&VLOOKUP(E5,AttackRiskStep!$A$3:$C$99,3,FALSE),"see Description")&IF(NOT(ISBLANK(F5))," -> "&CHAR(10)&VLOOKUP(F5,AttackRiskStep!$A$3:$C$99,3,FALSE),"")&IF(NOT(ISBLANK(G5))," -> "&CHAR(10)&VLOOKUP(G5,AttackRiskStep!$A$3:$C$99,3,FALSE),"") -> AS1 -> AS4 Gain access to a trusted operational environment -> Interrupting the EC-Master stack with a Denial of Service (DoS) attack | K5: Function and Availability | L5: customer | M5: EtherCAT | N5: Possible | O5: Catastrophic | P5: =VLOOKUP($N5,Likelihood!$A$3:$B$7,2,FALSE)*VLOOKUP($O5,Impact!$A$4:$B$8,2,FALSE) -> 15 | Q5: =VLOOKUP(P5,RPN!$B$6:$C$22,2) -> High | R5: MAC/frame filtering | S5: MAC/frame/CMD index filtering, waiting on ETG Document that covers this | T5: Help entry: Monitoring switch may not expose heavy traffic | Z5: =VLOOKUP($N5,Likelihood!$A$3:$C$7,2,FALSE)+RANDBETWEEN(-20,20)/100 -> 3.12 | AA5: =IF($Q5=AA$2,VLOOKUP($O5,Impact!$A$4:$B$8,2,FALSE)+RANDBETWEEN(-20,20)/100,NA()) -> #N/A | AB5: =IF($Q5=AB$2,VLOOKUP($O5,Impact!$A$4:$B$8,2,FALSE)+RANDBETWEEN(-20,20)/100,NA()) -> #N/A | AC5: =IF($Q5=AC$2,VLOOKUP($O5,Impact!$A$4:$B$8,2,FALSE)+RANDBETWEEN(-20,20)/100,NA()) -> 4.98
A6: 4 | B6: =I6 -> AS2 -> AS4 | C6: RAS, EAP, MbxGateway | D6: 46077 | E6: AS2 | F6: AS4 | H6: =IF(ISBLANK(E6),"s. D.",IF(ISBLANK(F6),E6,IF(ISBLANK(G6),F6,G6))) -> AS4 | I6: =IF(NOT(ISBLANK(E6)),E6,"")&IF(NOT(ISBLANK(F6))," -> "&F6,"")&IF(NOT(ISBLANK(G6))," -> "&G6,"") -> AS2 -> AS4 | J6: =I6&IF(NOT(ISBLANK(E6)),CHAR(10)&VLOOKUP(E6,AttackRiskStep!$A$3:$C$99,3,FALSE),"see Description")&IF(NOT(ISBLANK(F6))," -> "&CHAR(10)&VLOOKUP(F6,AttackRiskStep!$A$3:$C$99,3,FALSE),"")&IF(NOT(ISBLANK(G6))," -> "&CHAR(10)&VLOOKUP(G6,AttackRiskStep!$A$3:$C$99,3,FALSE),"") -> AS2 -> AS4 Gain access to a local network -> Interrupting the EC-Master stack with a Denial of Service (DoS) attack | K6: Function and Availability | L6: customer | M6: RAS | N6: Possible | O6: Catastrophic | P6: =VLOOKUP($N6,Likelihood!$A$3:$B$7,2,FALSE)*VLOOKUP($O6,Impact!$A$4:$B$8,2,FALSE) -> 15 | Q6: =VLOOKUP(P6,RPN!$B$6:$C$22,2) -> High | R6: Restrict access and encryption | S6: Currently are just n clients allowed, RAS cookie/signature, RAS TLS, Customer firewall/VPN/SSL | Z6: =VLOOKUP($N6,Likelihood!$A$3:$C$7,2,FALSE)+RANDBETWEEN(-20,20)/100 -> 3.08 | AA6: =IF($Q6=AA$2,VLOOKUP($O6,Impact!$A$4:$B$8,2,FALSE)+RANDBETWEEN(-20,20)/100,NA()) -> #N/A | AB6: =IF($Q6=AB$2,VLOOKUP($O6,Impact!$A$4:$B$8,2,FALSE)+RANDBETWEEN(-20,20)/100,NA()) -> #N/A | AC6: =IF($Q6=AC$2,VLOOKUP($O6,Impact!$A$4:$B$8,2,FALSE)+RANDBETWEEN(-20,20)/100,NA()) -> 5.11
A7: 5 | B7: =I7 -> AS1 -> AS6 | C7: WireShark sniffing of EtherCAT communication (and manipulating process data), EtherCAT men-in-the-middle | D7: 46077 | E7: AS1 | F7: AS6 | H7: =IF(ISBLANK(E7),"s. D.",IF(ISBLANK(F7),E7,IF(ISBLANK(G7),F7,G7))) -> AS6 | I7: =IF(NOT(ISBLANK(E7)),E7,"")&IF(NOT(ISBLANK(F7))," -> "&F7,"")&IF(NOT(ISBLANK(G7))," -> "&G7,"") -> AS1 -> AS6 | J7: =I7&IF(NOT(ISBLANK(E7)),CHAR(10)&VLOOKUP(E7,AttackRiskStep!$A$3:$C$99,3,FALSE),"see Description")&IF(NOT(ISBLANK(F7))," -> "&CHAR(10)&VLOOKUP(F7,AttackRiskStep!$A$3:$C$99,3,FALSE),"")&IF(NOT(ISBLANK(G7))," -> "&CHAR(10)&VLOOKUP(G7,AttackRiskStep!$A$3:$C$99,3,FALSE),"") -> AS1 -> AS6 Gain access to a trusted operational environment -> Spoofing / tampering with the EC-Master stack's outgoing communication | K7: Safety and Security | L7: customer | M7: EtherCAT | N7: Negligible | O7: Catastrophic | P7: =VLOOKUP($N7,Likelihood!$A$3:$B$7,2,FALSE)*VLOOKUP($O7,Impact!$A$4:$B$8,2,FALSE) -> 5 | Q7: =VLOOKUP(P7,RPN!$B$6:$C$22,2) -> Low | R7: Waiting for ETG Document | S7: Waiting for ETG Document | Z7: =VLOOKUP($N7,Likelihood!$A$3:$C$7,2,FALSE)+RANDBETWEEN(-20,20)/100 -> 1.15 | AA7: =IF($Q7=AA$2,VLOOKUP($O7,Impact!$A$4:$B$8,2,FALSE)+RANDBETWEEN(-20,20)/100,NA()) -> 5.15 | AB7: =IF($Q7=AB$2,VLOOKUP($O7,Impact!$A$4:$B$8,2,FALSE)+RANDBETWEEN(-20,20)/100,NA()) -> #N/A | AC7: =IF($Q7=AC$2,VLOOKUP($O7,Impact!$A$4:$B$8,2,FALSE)+RANDBETWEEN(-20,20)/100,NA()) -> #N/A
A8: 6 | B8: =I8 -> AS2 -> AS6 | C8: WireShark sniffing of RAS communication (and manipulating process data), e.g. RAS men-in-the-middle | D8: 46077 | E8: AS2 | F8: AS6 | H8: =IF(ISBLANK(E8),"s. D.",IF(ISBLANK(F8),E8,IF(ISBLANK(G8),F8,G8))) -> AS6 | I8: =IF(NOT(ISBLANK(E8)),E8,"")&IF(NOT(ISBLANK(F8))," -> "&F8,"")&IF(NOT(ISBLANK(G8))," -> "&G8,"") -> AS2 -> AS6 | J8: =I8&IF(NOT(ISBLANK(E8)),CHAR(10)&VLOOKUP(E8,AttackRiskStep!$A$3:$C$99,3,FALSE),"see Description")&IF(NOT(ISBLANK(F8))," -> "&CHAR(10)&VLOOKUP(F8,AttackRiskStep!$A$3:$C$99,3,FALSE),"")&IF(NOT(ISBLANK(G8))," -> "&CHAR(10)&VLOOKUP(G8,AttackRiskStep!$A$3:$C$99,3,FALSE),"") -> AS2 -> AS6 Gain access to a local network -> Spoofing / tampering with the EC-Master stack's outgoing communication | K8: Safety and Security | L8: acontis | M8: RAS | N8: Negligible | O8: Catastrophic | P8: =VLOOKUP($N8,Likelihood!$A$3:$B$7,2,FALSE)*VLOOKUP($O8,Impact!$A$4:$B$8,2,FALSE) -> 5 | Q8: =VLOOKUP(P8,RPN!$B$6:$C$22,2) -> Low | R8: Use RAS TLS and/or SPOC | S8: Use RAS TLS and/or SPOC | T8: Help entry | V8: open | Z8: =VLOOKUP($N8,Likelihood!$A$3:$C$7,2,FALSE)+RANDBETWEEN(-20,20)/100 -> 0.8 | AA8: =IF($Q8=AA$2,VLOOKUP($O8,Impact!$A$4:$B$8,2,FALSE)+RANDBETWEEN(-20,20)/100,NA()) -> 4.81 | AB8: =IF($Q8=AB$2,VLOOKUP($O8,Impact!$A$4:$B$8,2,FALSE)+RANDBETWEEN(-20,20)/100,NA()) -> #N/A | AC8: =IF($Q8=AC$2,VLOOKUP($O8,Impact!$A$4:$B$8,2,FALSE)+RANDBETWEEN(-20,20)/100,NA()) -> #N/A
A9: 7 | B9: =I9 -> AS1 -> AS7 | C9: e.g. prepared EtherCAT frame to set process data | D9: 46077 | E9: AS1 | F9: AS7 | H9: =IF(ISBLANK(E9),"s. D.",IF(ISBLANK(F9),E9,IF(ISBLANK(G9),F9,G9))) -> AS7 | I9: =IF(NOT(ISBLANK(E9)),E9,"")&IF(NOT(ISBLANK(F9))," -> "&F9,"")&IF(NOT(ISBLANK(G9))," -> "&G9,"") -> AS1 -> AS7 | J9: =I9&IF(NOT(ISBLANK(E9)),CHAR(10)&VLOOKUP(E9,AttackRiskStep!$A$3:$C$99,3,FALSE),"see Description")&IF(NOT(ISBLANK(F9))," -> "&CHAR(10)&VLOOKUP(F9,AttackRiskStep!$A$3:$C$99,3,FALSE),"")&IF(NOT(ISBLANK(G9))," -> "&CHAR(10)&VLOOKUP(G9,AttackRiskStep!$A$3:$C$99,3,FALSE),"") -> AS1 -> AS7 Gain access to a trusted operational environment -> Spoofing / tampering with the EC-Master stack's incoming communication | K9: Safety and Security | L9: customer | M9: EtherCAT | N9: Possible | O9: Catastrophic | P9: =VLOOKUP($N9,Likelihood!$A$3:$B$7,2,FALSE)*VLOOKUP($O9,Impact!$A$4:$B$8,2,FALSE) -> 15 | Q9: =VLOOKUP(P9,RPN!$B$6:$C$22,2) -> High | R9: Waiting for ETG Document | S9: Waiting for ETG Document | Z9: =VLOOKUP($N9,Likelihood!$A$3:$C$7,2,FALSE)+RANDBETWEEN(-20,20)/100 -> 2.93 | AA9: =IF($Q9=AA$2,VLOOKUP($O9,Impact!$A$4:$B$8,2,FALSE)+RANDBETWEEN(-20,20)/100,NA()) -> #N/A | AB9: =IF($Q9=AB$2,VLOOKUP($O9,Impact!$A$4:$B$8,2,FALSE)+RANDBETWEEN(-20,20)/100,NA()) -> #N/A | AC9: =IF($Q9=AC$2,VLOOKUP($O9,Impact!$A$4:$B$8,2,FALSE)+RANDBETWEEN(-20,20)/100,NA()) -> 5.16
A10: 8 | B10: =I10 -> AS2 -> AS7 | C10: e.g. prepared TCP RAS frame to set process data | D10: 46077 | E10: AS2 | F10: AS7 | H10: =IF(ISBLANK(E10),"s. D.",IF(ISBLANK(F10),E10,IF(ISBLANK(G10),F10,G10))) -> AS7 | I10: =IF(NOT(ISBLANK(E10)),E10,"")&IF(NOT(ISBLANK(F10))," -> "&F10,"")&IF(NOT(ISBLANK(G10))," -> "&G10,"") -> AS2 -> AS7 | J10: =I10&IF(NOT(ISBLANK(E10)),CHAR(10)&VLOOKUP(E10,AttackRiskStep!$A$3:$C$99,3,FALSE),"see Description")&IF(NOT(ISBLANK(F10))," -> "&CHAR(10)&VLOOKUP(F10,AttackRiskStep!$A$3:$C$99,3,FALSE),"")&IF(NOT(ISBLANK(G10))," -> "&CHAR(10)&VLOOKUP(G10,AttackRiskStep!$A$3:$C$99,3,FALSE),"") -> AS2 -> AS7 Gain access to a local network -> Spoofing / tampering with the EC-Master stack's incoming communication | K10: Safety and Security | L10: acontis | M10: RAS | N10: Unlikely | O10: Catastrophic | P10: =VLOOKUP($N10,Likelihood!$A$3:$B$7,2,FALSE)*VLOOKUP($O10,Impact!$A$4:$B$8,2,FALSE) -> 10 | Q10: =VLOOKUP(P10,RPN!$B$6:$C$22,2) -> Medium | R10: Use RAS TLS and/or SPOC | S10: Use RAS TLS and/or SPOC | Z10: =VLOOKUP($N10,Likelihood!$A$3:$C$7,2,FALSE)+RANDBETWEEN(-20,20)/100 -> 1.89 | AA10: =IF($Q10=AA$2,VLOOKUP($O10,Impact!$A$4:$B$8,2,FALSE)+RANDBETWEEN(-20,20)/100,NA()) -> #N/A | AB10: =IF($Q10=AB$2,VLOOKUP($O10,Impact!$A$4:$B$8,2,FALSE)+RANDBETWEEN(-20,20)/100,NA()) -> 5.19 | AC10: =IF($Q10=AC$2,VLOOKUP($O10,Impact!$A$4:$B$8,2,FALSE)+RANDBETWEEN(-20,20)/100,NA()) -> #N/A
A11: 9 | B11: =I11 -> AS1 -> AS3 -> AS10 | D11: 46079 | E11: AS1 | F11: AS3 | G11: AS10 | H11: =IF(ISBLANK(E11),"s. D.",IF(ISBLANK(F11),E11,IF(ISBLANK(G11),F11,G11))) -> AS10 | I11: =IF(NOT(ISBLANK(E11)),E11,"")&IF(NOT(ISBLANK(F11))," -> "&F11,"")&IF(NOT(ISBLANK(G11))," -> "&G11,"") -> AS1 -> AS3 -> AS10 | J11: =I11&IF(NOT(ISBLANK(E11)),CHAR(10)&VLOOKUP(E11,AttackRiskStep!$A$3:$C$99,3,FALSE),"see Description")&IF(NOT(ISBLANK(F11))," -> "&CHAR(10)&VLOOKUP(F11,AttackRiskStep!$A$3:$C$99,3,FALSE),"")&IF(NOT(ISBLANK(G11))," -> "&CHAR(10)&VLOOKUP(G11,AttackRiskStep!$A$3:$C$99,3,FALSE),"") -> AS1 -> AS3 -> AS10 Gain access to a trusted operational environment -> Compromising the EC-Master stack using a software vulnerability -> Attacking devices in the customer's network | K11: Safety and Security | L11: acontis | N11: Unlikely | O11: Catastrophic | P11: =VLOOKUP($N11,Likelihood!$A$3:$B$7,2,FALSE)*VLOOKUP($O11,Impact!$A$4:$B$8,2,FALSE) -> 10 | Q11: =VLOOKUP(P11,RPN!$B$6:$C$22,2) -> Medium | R11: =$R$27 & " + customer firewall" -> RID25: SW Tests + customer firewall | S11: =$S$27 & ", customer firewall, waiting for ETG Document" -> RID25: Virus scan, Static code analysis (Lint, CppCheck), Unit Tests, Functional Tests, Dynamic Tests, customer firewall, waiting for ETG Document | T11: Help entry: Customer should separate networks via firewalls | Z11: =VLOOKUP($N11,Likelihood!$A$3:$C$7,2,FALSE)+RANDBETWEEN(-20,20)/100 -> 2.03 | AA11: =IF($Q11=AA$2,VLOOKUP($O11,Impact!$A$4:$B$8,2,FALSE)+RANDBETWEEN(-20,20)/100,NA()) -> #N/A | AB11: =IF($Q11=AB$2,VLOOKUP($O11,Impact!$A$4:$B$8,2,FALSE)+RANDBETWEEN(-20,20)/100,NA()) -> 5.03 | AC11: =IF($Q11=AC$2,VLOOKUP($O11,Impact!$A$4:$B$8,2,FALSE)+RANDBETWEEN(-20,20)/100,NA()) -> #N/A
A12: 10 | B12: =I12 -> AS2 -> AS3 -> AS10 | D12: 46079 | E12: AS2 | F12: AS3 | G12: AS10 | H12: =IF(ISBLANK(E12),"s. D.",IF(ISBLANK(F12),E12,IF(ISBLANK(G12),F12,G12))) -> AS10 | I12: =IF(NOT(ISBLANK(E12)),E12,"")&IF(NOT(ISBLANK(F12))," -> "&F12,"")&IF(NOT(ISBLANK(G12))," -> "&G12,"") -> AS2 -> AS3 -> AS10 | J12: =I12&IF(NOT(ISBLANK(E12)),CHAR(10)&VLOOKUP(E12,AttackRiskStep!$A$3:$C$99,3,FALSE),"see Description")&IF(NOT(ISBLANK(F12))," -> "&CHAR(10)&VLOOKUP(F12,AttackRiskStep!$A$3:$C$99,3,FALSE),"")&IF(NOT(ISBLANK(G12))," -> "&CHAR(10)&VLOOKUP(G12,AttackRiskStep!$A$3:$C$99,3,FALSE),"") -> AS2 -> AS3 -> AS10 Gain access to a local network -> Compromising the EC-Master stack using a software vulnerability -> Attacking devices in the customer's network | K12: Safety and Security | L12: acontis | N12: Unlikely | O12: Catastrophic | P12: =VLOOKUP($N12,Likelihood!$A$3:$B$7,2,FALSE)*VLOOKUP($O12,Impact!$A$4:$B$8,2,FALSE) -> 10 | Q12: =VLOOKUP(P12,RPN!$B$6:$C$22,2) -> Medium | R12: =$R$27 & " + customer firewall" -> RID25: SW Tests + customer firewall | S12: =$S$27 & ", customer firewall, waiting for ETG Document" -> RID25: Virus scan, Static code analysis (Lint, CppCheck), Unit Tests, Functional Tests, Dynamic Tests, customer firewall, waiting for ETG Document | T12: Help entry: Customer should separate networks via firewalls | Z12: =VLOOKUP($N12,Likelihood!$A$3:$C$7,2,FALSE)+RANDBETWEEN(-20,20)/100 -> 2.03 | AA12: =IF($Q12=AA$2,VLOOKUP($O12,Impact!$A$4:$B$8,2,FALSE)+RANDBETWEEN(-20,20)/100,NA()) -> #N/A | AB12: =IF($Q12=AB$2,VLOOKUP($O12,Impact!$A$4:$B$8,2,FALSE)+RANDBETWEEN(-20,20)/100,NA()) -> 5.04 | AC12: =IF($Q12=AC$2,VLOOKUP($O12,Impact!$A$4:$B$8,2,FALSE)+RANDBETWEEN(-20,20)/100,NA()) -> #N/A
A13: 11 | B13: =I13 -> AS1 -> AS3 -> AS11 | D13: 46079 | E13: AS1 | F13: AS3 | G13: AS11 | H13: =IF(ISBLANK(E13),"s. D.",IF(ISBLANK(F13),E13,IF(ISBLANK(G13),F13,G13))) -> AS11 | I13: =IF(NOT(ISBLANK(E13)),E13,"")&IF(NOT(ISBLANK(F13))," -> "&F13,"")&IF(NOT(ISBLANK(G13))," -> "&G13,"") -> AS1 -> AS3 -> AS11 | J13: =I13&IF(NOT(ISBLANK(E13)),CHAR(10)&VLOOKUP(E13,AttackRiskStep!$A$3:$C$99,3,FALSE),"see Description")&IF(NOT(ISBLANK(F13))," -> "&CHAR(10)&VLOOKUP(F13,AttackRiskStep!$A$3:$C$99,3,FALSE),"")&IF(NOT(ISBLANK(G13))," -> "&CHAR(10)&VLOOKUP(G13,AttackRiskStep!$A$3:$C$99,3,FALSE),"") -> AS1 -> AS3 -> AS11 Gain access to a trusted operational environment -> Compromising the EC-Master stack using a software vulnerability -> Denial of Service (DoS) on the customer's network | K13: Safety and Security | L13: acontis | N13: Unlikely | O13: Catastrophic | P13: =VLOOKUP($N13,Likelihood!$A$3:$B$7,2,FALSE)*VLOOKUP($O13,Impact!$A$4:$B$8,2,FALSE) -> 10 | Q13: =VLOOKUP(P13,RPN!$B$6:$C$22,2) -> Medium | Z13: =VLOOKUP($N13,Likelihood!$A$3:$C$7,2,FALSE)+RANDBETWEEN(-20,20)/100 -> 1.82 | AA13: =IF($Q13=AA$2,VLOOKUP($O13,Impact!$A$4:$B$8,2,FALSE)+RANDBETWEEN(-20,20)/100,NA()) -> #N/A | AB13: =IF($Q13=AB$2,VLOOKUP($O13,Impact!$A$4:$B$8,2,FALSE)+RANDBETWEEN(-20,20)/100,NA()) -> 5.19 | AC13: =IF($Q13=AC$2,VLOOKUP($O13,Impact!$A$4:$B$8,2,FALSE)+RANDBETWEEN(-20,20)/100,NA()) -> #N/A
A14: 12 | B14: =I14 -> AS2 -> AS3 -> AS11 | D14: 46079 | E14: AS2 | F14: AS3 | G14: AS11 | H14: =IF(ISBLANK(E14),"s. D.",IF(ISBLANK(F14),E14,IF(ISBLANK(G14),F14,G14))) -> AS11 | I14: =IF(NOT(ISBLANK(E14)),E14,"")&IF(NOT(ISBLANK(F14))," -> "&F14,"")&IF(NOT(ISBLANK(G14))," -> "&G14,"") -> AS2 -> AS3 -> AS11 | J14: =I14&IF(NOT(ISBLANK(E14)),CHAR(10)&VLOOKUP(E14,AttackRiskStep!$A$3:$C$99,3,FALSE),"see Description")&IF(NOT(ISBLANK(F14))," -> "&CHAR(10)&VLOOKUP(F14,AttackRiskStep!$A$3:$C$99,3,FALSE),"")&IF(NOT(ISBLANK(G14))," -> "&CHAR(10)&VLOOKUP(G14,AttackRiskStep!$A$3:$C$99,3,FALSE),"") -> AS2 -> AS3 -> AS11 Gain access to a local network -> Compromising the EC-Master stack using a software vulnerability -> Denial of Service (DoS) on the customer's network | K14: Safety and Security | L14: acontis | N14: Unlikely | O14: Catastrophic | P14: =VLOOKUP($N14,Likelihood!$A$3:$B$7,2,FALSE)*VLOOKUP($O14,Impact!$A$4:$B$8,2,FALSE) -> 10 | Q14: =VLOOKUP(P14,RPN!$B$6:$C$22,2) -> Medium | Z14: =VLOOKUP($N14,Likelihood!$A$3:$C$7,2,FALSE)+RANDBETWEEN(-20,20)/100 -> 1.93 | AA14: =IF($Q14=AA$2,VLOOKUP($O14,Impact!$A$4:$B$8,2,FALSE)+RANDBETWEEN(-20,20)/100,NA()) -> #N/A | AB14: =IF($Q14=AB$2,VLOOKUP($O14,Impact!$A$4:$B$8,2,FALSE)+RANDBETWEEN(-20,20)/100,NA()) -> 5.03 | AC14: =IF($Q14=AC$2,VLOOKUP($O14,Impact!$A$4:$B$8,2,FALSE)+RANDBETWEEN(-20,20)/100,NA()) -> #N/A
A15: 13 | B15: =I15 -> AS1 -> AS14 | C15: Sporadically frames hit our RAS interface | D15: 46077 | E15: AS1 | F15: AS14 | H15: =IF(ISBLANK(E15),"s. D.",IF(ISBLANK(F15),E15,IF(ISBLANK(G15),F15,G15))) -> AS14 | I15: =IF(NOT(ISBLANK(E15)),E15,"")&IF(NOT(ISBLANK(F15))," -> "&F15,"")&IF(NOT(ISBLANK(G15))," -> "&G15,"") -> AS1 -> AS14 | J15: =I15&IF(NOT(ISBLANK(E15)),CHAR(10)&VLOOKUP(E15,AttackRiskStep!$A$3:$C$99,3,FALSE),"see Description")&IF(NOT(ISBLANK(F15))," -> "&CHAR(10)&VLOOKUP(F15,AttackRiskStep!$A$3:$C$99,3,FALSE),"")&IF(NOT(ISBLANK(G15))," -> "&CHAR(10)&VLOOKUP(G15,AttackRiskStep!$A$3:$C$99,3,FALSE),"") -> AS1 -> AS14 Gain access to a trusted operational environment -> Disrupting the EC-Master stack's communication over the local network | K15: Safety and Security | L15: customer | M15: RAS | N15: Possible | O15: Catastrophic | P15: =VLOOKUP($N15,Likelihood!$A$3:$B$7,2,FALSE)*VLOOKUP($O15,Impact!$A$4:$B$8,2,FALSE) -> 15 | Q15: =VLOOKUP(P15,RPN!$B$6:$C$22,2) -> High | Z15: =VLOOKUP($N15,Likelihood!$A$3:$C$7,2,FALSE)+RANDBETWEEN(-20,20)/100 -> 2.91 | AA15: =IF($Q15=AA$2,VLOOKUP($O15,Impact!$A$4:$B$8,2,FALSE)+RANDBETWEEN(-20,20)/100,NA()) -> #N/A | AB15: =IF($Q15=AB$2,VLOOKUP($O15,Impact!$A$4:$B$8,2,FALSE)+RANDBETWEEN(-20,20)/100,NA()) -> #N/A | AC15: =IF($Q15=AC$2,VLOOKUP($O15,Impact!$A$4:$B$8,2,FALSE)+RANDBETWEEN(-20,20)/100,NA()) -> 5.1
A16: 14 | B16: =I16 -> AS2 -> AS14 | C16: Sporadically frames hit our RAS interface | D16: 46077 | E16: AS2 | F16: AS14 | H16: =IF(ISBLANK(E16),"s. D.",IF(ISBLANK(F16),E16,IF(ISBLANK(G16),F16,G16))) -> AS14 | I16: =IF(NOT(ISBLANK(E16)),E16,"")&IF(NOT(ISBLANK(F16))," -> "&F16,"")&IF(NOT(ISBLANK(G16))," -> "&G16,"") -> AS2 -> AS14 | J16: =I16&IF(NOT(ISBLANK(E16)),CHAR(10)&VLOOKUP(E16,AttackRiskStep!$A$3:$C$99,3,FALSE),"see Description")&IF(NOT(ISBLANK(F16))," -> "&CHAR(10)&VLOOKUP(F16,AttackRiskStep!$A$3:$C$99,3,FALSE),"")&IF(NOT(ISBLANK(G16))," -> "&CHAR(10)&VLOOKUP(G16,AttackRiskStep!$A$3:$C$99,3,FALSE),"") -> AS2 -> AS14 Gain access to a local network -> Disrupting the EC-Master stack's communication over the local network | K16: Safety and Security | L16: acontis | M16: RAS | N16: Possible | O16: Catastrophic | P16: =VLOOKUP($N16,Likelihood!$A$3:$B$7,2,FALSE)*VLOOKUP($O16,Impact!$A$4:$B$8,2,FALSE) -> 15 | Q16: =VLOOKUP(P16,RPN!$B$6:$C$22,2) -> High | Z16: =VLOOKUP($N16,Likelihood!$A$3:$C$7,2,FALSE)+RANDBETWEEN(-20,20)/100 -> 2.85 | AA16: =IF($Q16=AA$2,VLOOKUP($O16,Impact!$A$4:$B$8,2,FALSE)+RANDBETWEEN(-20,20)/100,NA()) -> #N/A | AB16: =IF($Q16=AB$2,VLOOKUP($O16,Impact!$A$4:$B$8,2,FALSE)+RANDBETWEEN(-20,20)/100,NA()) -> #N/A | AC16: =IF($Q16=AC$2,VLOOKUP($O16,Impact!$A$4:$B$8,2,FALSE)+RANDBETWEEN(-20,20)/100,NA()) -> 5.04
A17: 15 | B17: =I17 -> AS1 -> AS16 | C17: e.g. changing the ENI file or parameters via RAS e.g. setting a value to be always one, manipulating the EoE subnetworks | D17: 46077 | E17: AS1 | F17: AS16 | H17: =IF(ISBLANK(E17),"s. D.",IF(ISBLANK(F17),E17,IF(ISBLANK(G17),F17,G17))) -> AS16 | I17: =IF(NOT(ISBLANK(E17)),E17,"")&IF(NOT(ISBLANK(F17))," -> "&F17,"")&IF(NOT(ISBLANK(G17))," -> "&G17,"") -> AS1 -> AS16 | J17: =I17&IF(NOT(ISBLANK(E17)),CHAR(10)&VLOOKUP(E17,AttackRiskStep!$A$3:$C$99,3,FALSE),"see Description")&IF(NOT(ISBLANK(F17))," -> "&CHAR(10)&VLOOKUP(F17,AttackRiskStep!$A$3:$C$99,3,FALSE),"")&IF(NOT(ISBLANK(G17))," -> "&CHAR(10)&VLOOKUP(G17,AttackRiskStep!$A$3:$C$99,3,FALSE),"") -> AS1 -> AS16 Gain access to a trusted operational environment -> Manipulating the EC-Master stack's configuration via its configuration interface | K17: Safety and Security | L17: acontis | M17: RAS, ENI | N17: Possible | O17: Catastrophic | P17: =VLOOKUP($N17,Likelihood!$A$3:$B$7,2,FALSE)*VLOOKUP($O17,Impact!$A$4:$B$8,2,FALSE) -> 15 | Q17: =VLOOKUP(P17,RPN!$B$6:$C$22,2) -> High | S17: maybe a hard coded CRC/SHA that ensures a distinct ENI | Z17: =VLOOKUP($N17,Likelihood!$A$3:$C$7,2,FALSE)+RANDBETWEEN(-20,20)/100 -> 3.09 | AA17: =IF($Q17=AA$2,VLOOKUP($O17,Impact!$A$4:$B$8,2,FALSE)+RANDBETWEEN(-20,20)/100,NA()) -> #N/A | AB17: =IF($Q17=AB$2,VLOOKUP($O17,Impact!$A$4:$B$8,2,FALSE)+RANDBETWEEN(-20,20)/100,NA()) -> #N/A | AC17: =IF($Q17=AC$2,VLOOKUP($O17,Impact!$A$4:$B$8,2,FALSE)+RANDBETWEEN(-20,20)/100,NA()) -> 5.14
A18: 16 | B18: =I18 -> AS2 -> AS16 | C18: e.g. changing the ENI file or parameters via RAS e.g. setting a value to be always one, manipulating the EoE subnetworks | D18: 46077 | E18: AS2 | F18: AS16 | H18: =IF(ISBLANK(E18),"s. D.",IF(ISBLANK(F18),E18,IF(ISBLANK(G18),F18,G18))) -> AS16 | I18: =IF(NOT(ISBLANK(E18)),E18,"")&IF(NOT(ISBLANK(F18))," -> "&F18,"")&IF(NOT(ISBLANK(G18))," -> "&G18,"") -> AS2 -> AS16 | J18: =I18&IF(NOT(ISBLANK(E18)),CHAR(10)&VLOOKUP(E18,AttackRiskStep!$A$3:$C$99,3,FALSE),"see Description")&IF(NOT(ISBLANK(F18))," -> "&CHAR(10)&VLOOKUP(F18,AttackRiskStep!$A$3:$C$99,3,FALSE),"")&IF(NOT(ISBLANK(G18))," -> "&CHAR(10)&VLOOKUP(G18,AttackRiskStep!$A$3:$C$99,3,FALSE),"") -> AS2 -> AS16 Gain access to a local network -> Manipulating the EC-Master stack's configuration via its configuration interface | K18: Safety and Security | L18: acontis | M18: RAS, ENI | N18: Possible | O18: Catastrophic | P18: =VLOOKUP($N18,Likelihood!$A$3:$B$7,2,FALSE)*VLOOKUP($O18,Impact!$A$4:$B$8,2,FALSE) -> 15 | Q18: =VLOOKUP(P18,RPN!$B$6:$C$22,2) -> High | S18: maybe a hard coded CRC/SHA that ensures a distinct ENI | Z18: =VLOOKUP($N18,Likelihood!$A$3:$C$7,2,FALSE)+RANDBETWEEN(-20,20)/100 -> 2.88 | AA18: =IF($Q18=AA$2,VLOOKUP($O18,Impact!$A$4:$B$8,2,FALSE)+RANDBETWEEN(-20,20)/100,NA()) -> #N/A | AB18: =IF($Q18=AB$2,VLOOKUP($O18,Impact!$A$4:$B$8,2,FALSE)+RANDBETWEEN(-20,20)/100,NA()) -> #N/A | AC18: =IF($Q18=AC$2,VLOOKUP($O18,Impact!$A$4:$B$8,2,FALSE)+RANDBETWEEN(-20,20)/100,NA()) -> 5.15
A19: 17 | B19: =I19 -> AS21 -> AS23 | C19: The attacker has access to the ENI file and manipulates it (e.g. variable mapping). The system is forced to reload the ENI file e.g. by a planned or unintended restart. | D19: 46078 | E19: AS21 | F19: AS23 | H19: =IF(ISBLANK(E19),"s. D.",IF(ISBLANK(F19),E19,IF(ISBLANK(G19),F19,G19))) -> AS23 | I19: =IF(NOT(ISBLANK(E19)),E19,"")&IF(NOT(ISBLANK(F19))," -> "&F19,"")&IF(NOT(ISBLANK(G19))," -> "&G19,"") -> AS21 -> AS23 | J19: =I19&IF(NOT(ISBLANK(E19)),CHAR(10)&VLOOKUP(E19,AttackRiskStep!$A$3:$C$99,3,FALSE),"see Description")&IF(NOT(ISBLANK(F19))," -> "&CHAR(10)&VLOOKUP(F19,AttackRiskStep!$A$3:$C$99,3,FALSE),"")&IF(NOT(ISBLANK(G19))," -> "&CHAR(10)&VLOOKUP(G19,AttackRiskStep!$A$3:$C$99,3,FALSE),"") -> AS21 -> AS23 Gaining physical access to the EC-Master stack (3rd party) -> Compromising the EC-Master stack with direct access to its persistent memory | K19: Safety and Security | L19: acontis | M19: ENI | N19: Possible | O19: Catastrophic | P19: =VLOOKUP($N19,Likelihood!$A$3:$B$7,2,FALSE)*VLOOKUP($O19,Impact!$A$4:$B$8,2,FALSE) -> 15 | Q19: =VLOOKUP(P19,RPN!$B$6:$C$22,2) -> High | S19: maybe a hard coded CRC/SHA that ensures a distinct ENI | Z19: =VLOOKUP($N19,Likelihood!$A$3:$C$7,2,FALSE)+RANDBETWEEN(-20,20)/100 -> 3.2 | AA19: =IF($Q19=AA$2,VLOOKUP($O19,Impact!$A$4:$B$8,2,FALSE)+RANDBETWEEN(-20,20)/100,NA()) -> #N/A | AB19: =IF($Q19=AB$2,VLOOKUP($O19,Impact!$A$4:$B$8,2,FALSE)+RANDBETWEEN(-20,20)/100,NA()) -> #N/A | AC19: =IF($Q19=AC$2,VLOOKUP($O19,Impact!$A$4:$B$8,2,FALSE)+RANDBETWEEN(-20,20)/100,NA()) -> 4.91
A20: 18 | B20: =I20 -> AS22 -> AS23 | C20: The customer has access to the ENI file and manipulates it (e.g. variable mapping). The system is forced to reload the ENI file e.g. by a planned or unintended restart. | D20: 46078 | E20: AS22 | F20: AS23 | H20: =IF(ISBLANK(E20),"s. D.",IF(ISBLANK(F20),E20,IF(ISBLANK(G20),F20,G20))) -> AS23 | I20: =IF(NOT(ISBLANK(E20)),E20,"")&IF(NOT(ISBLANK(F20))," -> "&F20,"")&IF(NOT(ISBLANK(G20))," -> "&G20,"") -> AS22 -> AS23 | J20: =I20&IF(NOT(ISBLANK(E20)),CHAR(10)&VLOOKUP(E20,AttackRiskStep!$A$3:$C$99,3,FALSE),"see Description")&IF(NOT(ISBLANK(F20))," -> "&CHAR(10)&VLOOKUP(F20,AttackRiskStep!$A$3:$C$99,3,FALSE),"")&IF(NOT(ISBLANK(G20))," -> "&CHAR(10)&VLOOKUP(G20,AttackRiskStep!$A$3:$C$99,3,FALSE),"") -> AS22 -> AS23 Gaining physical access to the EC-Master stack (customer) -> Compromising the EC-Master stack with direct access to its persistent memory | K20: Safety and Security | L20: customer | M20: ENI | N20: Likely | O20: Catastrophic | P20: =VLOOKUP($N20,Likelihood!$A$3:$B$7,2,FALSE)*VLOOKUP($O20,Impact!$A$4:$B$8,2,FALSE) -> 20 | Q20: =VLOOKUP(P20,RPN!$B$6:$C$22,2) -> High | S20: maybe a hard coded CRC/SHA that ensures a distinct ENI | Z20: =VLOOKUP($N20,Likelihood!$A$3:$C$7,2,FALSE)+RANDBETWEEN(-20,20)/100 -> 3.8 | AA20: =IF($Q20=AA$2,VLOOKUP($O20,Impact!$A$4:$B$8,2,FALSE)+RANDBETWEEN(-20,20)/100,NA()) -> #N/A | AB20: =IF($Q20=AB$2,VLOOKUP($O20,Impact!$A$4:$B$8,2,FALSE)+RANDBETWEEN(-20,20)/100,NA()) -> #N/A | AC20: =IF($Q20=AC$2,VLOOKUP($O20,Impact!$A$4:$B$8,2,FALSE)+RANDBETWEEN(-20,20)/100,NA()) -> 5.12
A21: 19 | B21: =I21 -> AS31 | C21: Inadmissible accessing a customer network from another customer network via the EC-Masters EoE or other protocol gateways. Two RAS endpoints are bridged by the virtual internal switch. | D21: 46077 | E21: AS31 | H21: =IF(ISBLANK(E21),"s. D.",IF(ISBLANK(F21),E21,IF(ISBLANK(G21),F21,G21))) -> AS31 | I21: =IF(NOT(ISBLANK(E21)),E21,"")&IF(NOT(ISBLANK(F21))," -> "&F21,"")&IF(NOT(ISBLANK(G21))," -> "&G21,"") -> AS31 | J21: =I21&IF(NOT(ISBLANK(E21)),CHAR(10)&VLOOKUP(E21,AttackRiskStep!$A$3:$C$99,3,FALSE),"see Description")&IF(NOT(ISBLANK(F21))," -> "&CHAR(10)&VLOOKUP(F21,AttackRiskStep!$A$3:$C$99,3,FALSE),"")&IF(NOT(ISBLANK(G21))," -> "&CHAR(10)&VLOOKUP(G21,AttackRiskStep!$A$3:$C$99,3,FALSE),"") -> AS31 Attacking a customer network from another customer network via the EC-Master stack's internal gateway | K21: Safety and Security | L21: acontis | M21: EoE | N21: Likely | O21: Catastrophic | P21: =VLOOKUP($N21,Likelihood!$A$3:$B$7,2,FALSE)*VLOOKUP($O21,Impact!$A$4:$B$8,2,FALSE) -> 20 | Q21: =VLOOKUP(P21,RPN!$B$6:$C$22,2) -> High | S21: Virtual TAPs with Firewall? | Z21: =VLOOKUP($N21,Likelihood!$A$3:$C$7,2,FALSE)+RANDBETWEEN(-20,20)/100 -> 4.11 | AA21: =IF($Q21=AA$2,VLOOKUP($O21,Impact!$A$4:$B$8,2,FALSE)+RANDBETWEEN(-20,20)/100,NA()) -> #N/A | AB21: =IF($Q21=AB$2,VLOOKUP($O21,Impact!$A$4:$B$8,2,FALSE)+RANDBETWEEN(-20,20)/100,NA()) -> #N/A | AC21: =IF($Q21=AC$2,VLOOKUP($O21,Impact!$A$4:$B$8,2,FALSE)+RANDBETWEEN(-20,20)/100,NA()) -> 5.01
A22: 20 | B22: =I22 & " " & L22 -> AS32 customer | C22: Customer or attacker on customers site misuses the EC-Master source code e.g. makes it public available | D22: 46078 | E22: AS32 | H22: =IF(ISBLANK(E22),"s. D.",IF(ISBLANK(F22),E22,IF(ISBLANK(G22),F22,G22))) -> AS32 | I22: =IF(NOT(ISBLANK(E22)),E22,"")&IF(NOT(ISBLANK(F22))," -> "&F22,"")&IF(NOT(ISBLANK(G22))," -> "&G22,"") -> AS32 | J22: =I22&IF(NOT(ISBLANK(E22)),CHAR(10)&VLOOKUP(E22,AttackRiskStep!$A$3:$C$99,3,FALSE),"see Description")&IF(NOT(ISBLANK(F22))," -> "&CHAR(10)&VLOOKUP(F22,AttackRiskStep!$A$3:$C$99,3,FALSE),"")&IF(NOT(ISBLANK(G22))," -> "&CHAR(10)&VLOOKUP(G22,AttackRiskStep!$A$3:$C$99,3,FALSE),"") -> AS32 Extracting or misusing the acontis technology GmbH IP | K22: Financial and Legal | L22: customer | N22: Likely | O22: Major | P22: =VLOOKUP($N22,Likelihood!$A$3:$B$7,2,FALSE)*VLOOKUP($O22,Impact!$A$4:$B$8,2,FALSE) -> 16 | Q22: =VLOOKUP(P22,RPN!$B$6:$C$22,2) -> High | Z22: =VLOOKUP($N22,Likelihood!$A$3:$C$7,2,FALSE)+RANDBETWEEN(-20,20)/100 -> 3.99 | AA22: =IF($Q22=AA$2,VLOOKUP($O22,Impact!$A$4:$B$8,2,FALSE)+RANDBETWEEN(-20,20)/100,NA()) -> #N/A | AB22: =IF($Q22=AB$2,VLOOKUP($O22,Impact!$A$4:$B$8,2,FALSE)+RANDBETWEEN(-20,20)/100,NA()) -> #N/A | AC22: =IF($Q22=AC$2,VLOOKUP($O22,Impact!$A$4:$B$8,2,FALSE)+RANDBETWEEN(-20,20)/100,NA()) -> 3.98
A23: 21 | B23: =I23 & " " & L23 -> AS32 acontis | C23: Employee or internal attacker misuses the EC-Master source code e.g. uses a non-licensed feature | D23: 46078 | E23: AS32 | H23: =IF(ISBLANK(E23),"s. D.",IF(ISBLANK(F23),E23,IF(ISBLANK(G23),F23,G23))) -> AS32 | I23: =IF(NOT(ISBLANK(E23)),E23,"")&IF(NOT(ISBLANK(F23))," -> "&F23,"")&IF(NOT(ISBLANK(G23))," -> "&G23,"") -> AS32 | J23: =I23&IF(NOT(ISBLANK(E23)),CHAR(10)&VLOOKUP(E23,AttackRiskStep!$A$3:$C$99,3,FALSE),"see Description")&IF(NOT(ISBLANK(F23))," -> "&CHAR(10)&VLOOKUP(F23,AttackRiskStep!$A$3:$C$99,3,FALSE),"")&IF(NOT(ISBLANK(G23))," -> "&CHAR(10)&VLOOKUP(G23,AttackRiskStep!$A$3:$C$99,3,FALSE),"") -> AS32 Extracting or misusing the acontis technology GmbH IP | K23: Financial and Legal | L23: acontis | N23: Likely | O23: Moderate | P23: =VLOOKUP($N23,Likelihood!$A$3:$B$7,2,FALSE)*VLOOKUP($O23,Impact!$A$4:$B$8,2,FALSE) -> 12 | Q23: =VLOOKUP(P23,RPN!$B$6:$C$22,2) -> Medium | Z23: =VLOOKUP($N23,Likelihood!$A$3:$C$7,2,FALSE)+RANDBETWEEN(-20,20)/100 -> 3.98 | AA23: =IF($Q23=AA$2,VLOOKUP($O23,Impact!$A$4:$B$8,2,FALSE)+RANDBETWEEN(-20,20)/100,NA()) -> #N/A | AB23: =IF($Q23=AB$2,VLOOKUP($O23,Impact!$A$4:$B$8,2,FALSE)+RANDBETWEEN(-20,20)/100,NA()) -> 3.18 | AC23: =IF($Q23=AC$2,VLOOKUP($O23,Impact!$A$4:$B$8,2,FALSE)+RANDBETWEEN(-20,20)/100,NA()) -> #N/A
A24: 22 | B24: =I24 -> AS37 | C24: intentionally by an attacker or unintentially by mistake | D24: 46078 | E24: AS37 | H24: =IF(ISBLANK(E24),"s. D.",IF(ISBLANK(F24),E24,IF(ISBLANK(G24),F24,G24))) -> AS37 | I24: =IF(NOT(ISBLANK(E24)),E24,"")&IF(NOT(ISBLANK(F24))," -> "&F24,"")&IF(NOT(ISBLANK(G24))," -> "&G24,"") -> AS37 | J24: =I24&IF(NOT(ISBLANK(E24)),CHAR(10)&VLOOKUP(E24,AttackRiskStep!$A$3:$C$99,3,FALSE),"see Description")&IF(NOT(ISBLANK(F24))," -> "&CHAR(10)&VLOOKUP(F24,AttackRiskStep!$A$3:$C$99,3,FALSE),"")&IF(NOT(ISBLANK(G24))," -> "&CHAR(10)&VLOOKUP(G24,AttackRiskStep!$A$3:$C$99,3,FALSE),"") -> AS37 The EC-Master stack is manipulated during EC-Master stackion and consequently behaves maliciously | K24: Safety and Security | L24: acontis | N24: Possible | O24: Catastrophic | P24: =VLOOKUP($N24,Likelihood!$A$3:$B$7,2,FALSE)*VLOOKUP($O24,Impact!$A$4:$B$8,2,FALSE) -> 15 | Q24: =VLOOKUP(P24,RPN!$B$6:$C$22,2) -> High | S24: Tests, Access rights, Firewall check before FTP, Upload just by a certain instance e.g. build server, with certain check mechanisms and file hashes | Z24: =VLOOKUP($N24,Likelihood!$A$3:$C$7,2,FALSE)+RANDBETWEEN(-20,20)/100 -> 3.01 | AA24: =IF($Q24=AA$2,VLOOKUP($O24,Impact!$A$4:$B$8,2,FALSE)+RANDBETWEEN(-20,20)/100,NA()) -> #N/A | AB24: =IF($Q24=AB$2,VLOOKUP($O24,Impact!$A$4:$B$8,2,FALSE)+RANDBETWEEN(-20,20)/100,NA()) -> #N/A | AC24: =IF($Q24=AC$2,VLOOKUP($O24,Impact!$A$4:$B$8,2,FALSE)+RANDBETWEEN(-20,20)/100,NA()) -> 5.14
A25: 23 | B25: =I25 -> AS38 | D25: 46078 | E25: AS38 | H25: =IF(ISBLANK(E25),"s. D.",IF(ISBLANK(F25),E25,IF(ISBLANK(G25),F25,G25))) -> AS38 | I25: =IF(NOT(ISBLANK(E25)),E25,"")&IF(NOT(ISBLANK(F25))," -> "&F25,"")&IF(NOT(ISBLANK(G25))," -> "&G25,"") -> AS38 | J25: =I25&IF(NOT(ISBLANK(E25)),CHAR(10)&VLOOKUP(E25,AttackRiskStep!$A$3:$C$99,3,FALSE),"see Description")&IF(NOT(ISBLANK(F25))," -> "&CHAR(10)&VLOOKUP(F25,AttackRiskStep!$A$3:$C$99,3,FALSE),"")&IF(NOT(ISBLANK(G25))," -> "&CHAR(10)&VLOOKUP(G25,AttackRiskStep!$A$3:$C$99,3,FALSE),"") -> AS38 Manipulated parts from the supply chain are integrated into the EC-Master stack, leading to the EC-Master stack behaving maliciously | K25: Safety and Security | L25: acontis | M25: eXpat | N25: Unlikely | O25: Catastrophic | P25: =VLOOKUP($N25,Likelihood!$A$3:$B$7,2,FALSE)*VLOOKUP($O25,Impact!$A$4:$B$8,2,FALSE) -> 10 | Q25: =VLOOKUP(P25,RPN!$B$6:$C$22,2) -> Medium | S25: We must ensure that updates of the parts are downloaded/cloned from the official site of the project e.g. eXpat. If e.g. the eXpat library is tampered it's nearly impossible to get aware of the manipulation without extensive tests before integration. | Z25: =VLOOKUP($N25,Likelihood!$A$3:$C$7,2,FALSE)+RANDBETWEEN(-20,20)/100 -> 1.83 | AA25: =IF($Q25=AA$2,VLOOKUP($O25,Impact!$A$4:$B$8,2,FALSE)+RANDBETWEEN(-20,20)/100,NA()) -> #N/A | AB25: =IF($Q25=AB$2,VLOOKUP($O25,Impact!$A$4:$B$8,2,FALSE)+RANDBETWEEN(-20,20)/100,NA()) -> 5.11 | AC25: =IF($Q25=AC$2,VLOOKUP($O25,Impact!$A$4:$B$8,2,FALSE)+RANDBETWEEN(-20,20)/100,NA()) -> #N/A
A26: 24 | B26: =I26 & " in unmaintained supply chain" -> AS3 in unmaintained supply chain | C26: There are Common Vulnerabilities and Exposures (CVE) for a part of the supply chain but nobody maintains the used part anymore e.g. eXpat | D26: 46078 | E26: AS3 | H26: =IF(ISBLANK(E26),"s. D.",IF(ISBLANK(F26),E26,IF(ISBLANK(G26),F26,G26))) -> AS3 | I26: =IF(NOT(ISBLANK(E26)),E26,"")&IF(NOT(ISBLANK(F26))," -> "&F26,"")&IF(NOT(ISBLANK(G26))," -> "&G26,"") -> AS3 | J26: =I26&IF(NOT(ISBLANK(E26)),CHAR(10)&VLOOKUP(E26,AttackRiskStep!$A$3:$C$99,3,FALSE),"see Description")&IF(NOT(ISBLANK(F26))," -> "&CHAR(10)&VLOOKUP(F26,AttackRiskStep!$A$3:$C$99,3,FALSE),"")&IF(NOT(ISBLANK(G26))," -> "&CHAR(10)&VLOOKUP(G26,AttackRiskStep!$A$3:$C$99,3,FALSE),"") -> AS3 Compromising the EC-Master stack using a software vulnerability | K26: Safety and Security | L26: acontis | M26: eXpat | N26: Unlikely | O26: Moderate | P26: =VLOOKUP($N26,Likelihood!$A$3:$B$7,2,FALSE)*VLOOKUP($O26,Impact!$A$4:$B$8,2,FALSE) -> 6 | Q26: =VLOOKUP(P26,RPN!$B$6:$C$22,2) -> Medium | S26: we have the source | Z26: =VLOOKUP($N26,Likelihood!$A$3:$C$7,2,FALSE)+RANDBETWEEN(-20,20)/100 -> 1.81 | AA26: =IF($Q26=AA$2,VLOOKUP($O26,Impact!$A$4:$B$8,2,FALSE)+RANDBETWEEN(-20,20)/100,NA()) -> #N/A | AB26: =IF($Q26=AB$2,VLOOKUP($O26,Impact!$A$4:$B$8,2,FALSE)+RANDBETWEEN(-20,20)/100,NA()) -> 3.13 | AC26: =IF($Q26=AC$2,VLOOKUP($O26,Impact!$A$4:$B$8,2,FALSE)+RANDBETWEEN(-20,20)/100,NA()) -> #N/A
A27: 25 | B27: =I27 -> AS3 | D27: 46078 | E27: AS3 | H27: =IF(ISBLANK(E27),"s. D.",IF(ISBLANK(F27),E27,IF(ISBLANK(G27),F27,G27))) -> AS3 | I27: =IF(NOT(ISBLANK(E27)),E27,"")&IF(NOT(ISBLANK(F27))," -> "&F27,"")&IF(NOT(ISBLANK(G27))," -> "&G27,"") -> AS3 | J27: =I27&IF(NOT(ISBLANK(E27)),CHAR(10)&VLOOKUP(E27,AttackRiskStep!$A$3:$C$99,3,FALSE),"see Description")&IF(NOT(ISBLANK(F27))," -> "&CHAR(10)&VLOOKUP(F27,AttackRiskStep!$A$3:$C$99,3,FALSE),"")&IF(NOT(ISBLANK(G27))," -> "&CHAR(10)&VLOOKUP(G27,AttackRiskStep!$A$3:$C$99,3,FALSE),"") -> AS3 Compromising the EC-Master stack using a software vulnerability | K27: Safety and Security | L27: acontis | N27: Unlikely | O27: Catastrophic | P27: =VLOOKUP($N27,Likelihood!$A$3:$B$7,2,FALSE)*VLOOKUP($O27,Impact!$A$4:$B$8,2,FALSE) -> 10 | Q27: =VLOOKUP(P27,RPN!$B$6:$C$22,2) -> Medium | R27: ="RID" & A27 & ": SW Tests" -> RID25: SW Tests | S27: ="RID" & A27 & ": Virus scan, Static code analysis (Lint, CppCheck), Unit Tests, Functional Tests, Dynamic Tests" -> RID25: Virus scan, Static code analysis (Lint, CppCheck), Unit Tests, Functional Tests, Dynamic Tests | Z27: =VLOOKUP($N27,Likelihood!$A$3:$C$7,2,FALSE)+RANDBETWEEN(-20,20)/100 -> 1.86 | AA27: =IF($Q27=AA$2,VLOOKUP($O27,Impact!$A$4:$B$8,2,FALSE)+RANDBETWEEN(-20,20)/100,NA()) -> #N/A | AB27: =IF($Q27=AB$2,VLOOKUP($O27,Impact!$A$4:$B$8,2,FALSE)+RANDBETWEEN(-20,20)/100,NA()) -> 5.12 | AC27: =IF($Q27=AC$2,VLOOKUP($O27,Impact!$A$4:$B$8,2,FALSE)+RANDBETWEEN(-20,20)/100,NA()) -> #N/A
A28: 26 | B28: Parts of the supply chain are not maintained anymore | C28: There are strongly needed features for a part of the supply chain but nobody maintains the used part anymore | D28: 46078 | H28: =IF(ISBLANK(E28),"s. D.",IF(ISBLANK(F28),E28,IF(ISBLANK(G28),F28,G28))) -> s. D. | I28: =IF(NOT(ISBLANK(E28)),E28,"")&IF(NOT(ISBLANK(F28))," -> "&F28,"")&IF(NOT(ISBLANK(G28))," -> "&G28,"") | J28: =I28&IF(NOT(ISBLANK(E28)),CHAR(10)&VLOOKUP(E28,AttackRiskStep!$A$3:$C$99,3,FALSE),"see Description")&IF(NOT(ISBLANK(F28))," -> "&CHAR(10)&VLOOKUP(F28,AttackRiskStep!$A$3:$C$99,3,FALSE),"")&IF(NOT(ISBLANK(G28))," -> "&CHAR(10)&VLOOKUP(G28,AttackRiskStep!$A$3:$C$99,3,FALSE),"") -> see Description | K28: Function and Availability | L28: acontis | M28: eXpat | N28: Unlikely | O28: Minor | P28: =VLOOKUP($N28,Likelihood!$A$3:$B$7,2,FALSE)*VLOOKUP($O28,Impact!$A$4:$B$8,2,FALSE) -> 4 | Q28: =VLOOKUP(P28,RPN!$B$6:$C$22,2) -> Low | S28: we have the source | Z28: =VLOOKUP($N28,Likelihood!$A$3:$C$7,2,FALSE)+RANDBETWEEN(-20,20)/100 -> 2.01 | AA28: =IF($Q28=AA$2,VLOOKUP($O28,Impact!$A$4:$B$8,2,FALSE)+RANDBETWEEN(-20,20)/100,NA()) -> 1.84 | AB28: =IF($Q28=AB$2,VLOOKUP($O28,Impact!$A$4:$B$8,2,FALSE)+RANDBETWEEN(-20,20)/100,NA()) -> #N/A | AC28: =IF($Q28=AC$2,VLOOKUP($O28,Impact!$A$4:$B$8,2,FALSE)+RANDBETWEEN(-20,20)/100,NA()) -> #N/A
A29: 27 | B29: =I29 -> AS39 | C29: Configuration could be read out via the RAS interface e.g. with the EC-Engineer. | D29: 46078 | E29: AS39 | H29: =IF(ISBLANK(E29),"s. D.",IF(ISBLANK(F29),E29,IF(ISBLANK(G29),F29,G29))) -> AS39 | I29: =IF(NOT(ISBLANK(E29)),E29,"")&IF(NOT(ISBLANK(F29))," -> "&F29,"")&IF(NOT(ISBLANK(G29))," -> "&G29,"") -> AS39 | J29: =I29&IF(NOT(ISBLANK(E29)),CHAR(10)&VLOOKUP(E29,AttackRiskStep!$A$3:$C$99,3,FALSE),"see Description")&IF(NOT(ISBLANK(F29))," -> "&CHAR(10)&VLOOKUP(F29,AttackRiskStep!$A$3:$C$99,3,FALSE),"")&IF(NOT(ISBLANK(G29))," -> "&CHAR(10)&VLOOKUP(G29,AttackRiskStep!$A$3:$C$99,3,FALSE),"") -> AS39 Data extraction from the EC-Master stack's volatile memory | K29: Financial and Legal | L29: acontis | N29: Unlikely | O29: Minor | P29: =VLOOKUP($N29,Likelihood!$A$3:$B$7,2,FALSE)*VLOOKUP($O29,Impact!$A$4:$B$8,2,FALSE) -> 4 | Q29: =VLOOKUP(P29,RPN!$B$6:$C$22,2) -> Low | S29: SPOC, customer help, Token mechanism with access rights, Document securtity issues and the already available associated counter measures and mechanisms | Z29: =VLOOKUP($N29,Likelihood!$A$3:$C$7,2,FALSE)+RANDBETWEEN(-20,20)/100 -> 1.99 | AA29: =IF($Q29=AA$2,VLOOKUP($O29,Impact!$A$4:$B$8,2,FALSE)+RANDBETWEEN(-20,20)/100,NA()) -> 1.97 | AB29: =IF($Q29=AB$2,VLOOKUP($O29,Impact!$A$4:$B$8,2,FALSE)+RANDBETWEEN(-20,20)/100,NA()) -> #N/A | AC29: =IF($Q29=AC$2,VLOOKUP($O29,Impact!$A$4:$B$8,2,FALSE)+RANDBETWEEN(-20,20)/100,NA()) -> #N/A
A30: 28 | B30: Delivering the wrong package | C30: Currently it's not very unlikely that an employee selects the wrong package in a delivery | D30: 46078 | H30: =IF(ISBLANK(E30),"s. D.",IF(ISBLANK(F30),E30,IF(ISBLANK(G30),F30,G30))) -> s. D. | I30: =IF(NOT(ISBLANK(E30)),E30,"")&IF(NOT(ISBLANK(F30))," -> "&F30,"")&IF(NOT(ISBLANK(G30))," -> "&G30,"") | J30: =I30&IF(NOT(ISBLANK(E30)),CHAR(10)&VLOOKUP(E30,AttackRiskStep!$A$3:$C$99,3,FALSE),"see Description")&IF(NOT(ISBLANK(F30))," -> "&CHAR(10)&VLOOKUP(F30,AttackRiskStep!$A$3:$C$99,3,FALSE),"")&IF(NOT(ISBLANK(G30))," -> "&CHAR(10)&VLOOKUP(G30,AttackRiskStep!$A$3:$C$99,3,FALSE),"") -> see Description | K30: Financial and Legal | L30: acontis | N30: Unlikely | O30: Negligible | P30: =VLOOKUP($N30,Likelihood!$A$3:$B$7,2,FALSE)*VLOOKUP($O30,Impact!$A$4:$B$8,2,FALSE) -> 2 | Q30: =VLOOKUP(P30,RPN!$B$6:$C$22,2) -> Low | Z30: =VLOOKUP($N30,Likelihood!$A$3:$C$7,2,FALSE)+RANDBETWEEN(-20,20)/100 -> 1.81 | AA30: =IF($Q30=AA$2,VLOOKUP($O30,Impact!$A$4:$B$8,2,FALSE)+RANDBETWEEN(-20,20)/100,NA()) -> 1.2 | AB30: =IF($Q30=AB$2,VLOOKUP($O30,Impact!$A$4:$B$8,2,FALSE)+RANDBETWEEN(-20,20)/100,NA()) -> #N/A | AC30: =IF($Q30=AC$2,VLOOKUP($O30,Impact!$A$4:$B$8,2,FALSE)+RANDBETWEEN(-20,20)/100,NA()) -> #N/A
A31: 29 | B31: =I31 -> AS42 | C31: Cusotmer ignores license provisions or passes by our licensing mechanims | D31: 46079 | E31: AS42 | H31: =IF(ISBLANK(E31),"s. D.",IF(ISBLANK(F31),E31,IF(ISBLANK(G31),F31,G31))) -> AS42 | I31: =IF(NOT(ISBLANK(E31)),E31,"")&IF(NOT(ISBLANK(F31))," -> "&F31,"")&IF(NOT(ISBLANK(G31))," -> "&G31,"") -> AS42 | J31: =I31&IF(NOT(ISBLANK(E31)),CHAR(10)&VLOOKUP(E31,AttackRiskStep!$A$3:$C$99,3,FALSE),"see Description")&IF(NOT(ISBLANK(F31))," -> "&CHAR(10)&VLOOKUP(F31,AttackRiskStep!$A$3:$C$99,3,FALSE),"")&IF(NOT(ISBLANK(G31))," -> "&CHAR(10)&VLOOKUP(G31,AttackRiskStep!$A$3:$C$99,3,FALSE),"") -> AS42 Circumvention of licence provisions or bypassing of licensing procedures | K31: Financial and Legal | L31: acontis | N31: Possible | O31: Moderate | P31: =VLOOKUP($N31,Likelihood!$A$3:$B$7,2,FALSE)*VLOOKUP($O31,Impact!$A$4:$B$8,2,FALSE) -> 9 | Q31: =VLOOKUP(P31,RPN!$B$6:$C$22,2) -> Medium | Z31: =VLOOKUP($N31,Likelihood!$A$3:$C$7,2,FALSE)+RANDBETWEEN(-20,20)/100 -> 2.82 | AA31: =IF($Q31=AA$2,VLOOKUP($O31,Impact!$A$4:$B$8,2,FALSE)+RANDBETWEEN(-20,20)/100,NA()) -> #N/A | AB31: =IF($Q31=AB$2,VLOOKUP($O31,Impact!$A$4:$B$8,2,FALSE)+RANDBETWEEN(-20,20)/100,NA()) -> 3.07 | AC31: =IF($Q31=AC$2,VLOOKUP($O31,Impact!$A$4:$B$8,2,FALSE)+RANDBETWEEN(-20,20)/100,NA()) -> #N/A
A32: 30 | B32: =I32 | H32: =IF(ISBLANK(E32),"s. D.",IF(ISBLANK(F32),E32,IF(ISBLANK(G32),F32,G32))) -> s. D. | I32: =IF(NOT(ISBLANK(E32)),E32,"")&IF(NOT(ISBLANK(F32))," -> "&F32,"")&IF(NOT(ISBLANK(G32))," -> "&G32,"") | J32: =I32&IF(NOT(ISBLANK(E32)),CHAR(10)&VLOOKUP(E32,AttackRiskStep!$A$3:$C$99,3,FALSE),"see Description")&IF(NOT(ISBLANK(F32))," -> "&CHAR(10)&VLOOKUP(F32,AttackRiskStep!$A$3:$C$99,3,FALSE),"")&IF(NOT(ISBLANK(G32))," -> "&CHAR(10)&VLOOKUP(G32,AttackRiskStep!$A$3:$C$99,3,FALSE),"") -> see Description | P32: =VLOOKUP($N32,Likelihood!$A$3:$B$7,2,FALSE)*VLOOKUP($O32,Impact!$A$4:$B$8,2,FALSE) -> #N/A | Q32: =VLOOKUP(P32,RPN!$B$6:$C$22,2) -> #N/A | Z32: =VLOOKUP($N32,Likelihood!$A$3:$C$7,2,FALSE)+RANDBETWEEN(-20,20)/100 -> #N/A | AA32: =IF($Q32=AA$2,VLOOKUP($O32,Impact!$A$4:$B$8,2,FALSE)+RANDBETWEEN(-20,20)/100,NA()) -> #N/A | AB32: =IF($Q32=AB$2,VLOOKUP($O32,Impact!$A$4:$B$8,2,FALSE)+RANDBETWEEN(-20,20)/100,NA()) -> #N/A | AC32: =IF($Q32=AC$2,VLOOKUP($O32,Impact!$A$4:$B$8,2,FALSE)+RANDBETWEEN(-20,20)/100,NA()) -> #N/A
A33: 31 | B33: =I33 | H33: =IF(ISBLANK(E33),"s. D.",IF(ISBLANK(F33),E33,IF(ISBLANK(G33),F33,G33))) -> s. D. | I33: =IF(NOT(ISBLANK(E33)),E33,"")&IF(NOT(ISBLANK(F33))," -> "&F33,"")&IF(NOT(ISBLANK(G33))," -> "&G33,"") | J33: =I33&IF(NOT(ISBLANK(E33)),CHAR(10)&VLOOKUP(E33,AttackRiskStep!$A$3:$C$99,3,FALSE),"see Description")&IF(NOT(ISBLANK(F33))," -> "&CHAR(10)&VLOOKUP(F33,AttackRiskStep!$A$3:$C$99,3,FALSE),"")&IF(NOT(ISBLANK(G33))," -> "&CHAR(10)&VLOOKUP(G33,AttackRiskStep!$A$3:$C$99,3,FALSE),"") -> see Description | P33: =VLOOKUP($N33,Likelihood!$A$3:$B$7,2,FALSE)*VLOOKUP($O33,Impact!$A$4:$B$8,2,FALSE) -> #N/A | Q33: =VLOOKUP(P33,RPN!$B$6:$C$22,2) -> #N/A | Z33: =VLOOKUP($N33,Likelihood!$A$3:$C$7,2,FALSE)+RANDBETWEEN(-20,20)/100 -> #N/A | AA33: =IF($Q33=AA$2,VLOOKUP($O33,Impact!$A$4:$B$8,2,FALSE)+RANDBETWEEN(-20,20)/100,NA()) -> #N/A | AB33: =IF($Q33=AB$2,VLOOKUP($O33,Impact!$A$4:$B$8,2,FALSE)+RANDBETWEEN(-20,20)/100,NA()) -> #N/A | AC33: =IF($Q33=AC$2,VLOOKUP($O33,Impact!$A$4:$B$8,2,FALSE)+RANDBETWEEN(-20,20)/100,NA()) -> #N/A
A34: 32 | B34: =I34 | H34: =IF(ISBLANK(E34),"s. D.",IF(ISBLANK(F34),E34,IF(ISBLANK(G34),F34,G34))) -> s. D. | I34: =IF(NOT(ISBLANK(E34)),E34,"")&IF(NOT(ISBLANK(F34))," -> "&F34,"")&IF(NOT(ISBLANK(G34))," -> "&G34,"") | J34: =I34&IF(NOT(ISBLANK(E34)),CHAR(10)&VLOOKUP(E34,AttackRiskStep!$A$3:$C$99,3,FALSE),"see Description")&IF(NOT(ISBLANK(F34))," -> "&CHAR(10)&VLOOKUP(F34,AttackRiskStep!$A$3:$C$99,3,FALSE),"")&IF(NOT(ISBLANK(G34))," -> "&CHAR(10)&VLOOKUP(G34,AttackRiskStep!$A$3:$C$99,3,FALSE),"") -> see Description | P34: =VLOOKUP($N34,Likelihood!$A$3:$B$7,2,FALSE)*VLOOKUP($O34,Impact!$A$4:$B$8,2,FALSE) -> #N/A | Q34: =VLOOKUP(P34,RPN!$B$6:$C$22,2) -> #N/A | Z34: =VLOOKUP($N34,Likelihood!$A$3:$C$7,2,FALSE)+RANDBETWEEN(-20,20)/100 -> #N/A | AA34: =IF($Q34=AA$2,VLOOKUP($O34,Impact!$A$4:$B$8,2,FALSE)+RANDBETWEEN(-20,20)/100,NA()) -> #N/A | AB34: =IF($Q34=AB$2,VLOOKUP($O34,Impact!$A$4:$B$8,2,FALSE)+RANDBETWEEN(-20,20)/100,NA()) -> #N/A | AC34: =IF($Q34=AC$2,VLOOKUP($O34,Impact!$A$4:$B$8,2,FALSE)+RANDBETWEEN(-20,20)/100,NA()) -> #N/A
A35: 33 | B35: =I35 | H35: =IF(ISBLANK(E35),"s. D.",IF(ISBLANK(F35),E35,IF(ISBLANK(G35),F35,G35))) -> s. D. | I35: =IF(NOT(ISBLANK(E35)),E35,"")&IF(NOT(ISBLANK(F35))," -> "&F35,"")&IF(NOT(ISBLANK(G35))," -> "&G35,"") | J35: =I35&IF(NOT(ISBLANK(E35)),CHAR(10)&VLOOKUP(E35,AttackRiskStep!$A$3:$C$99,3,FALSE),"see Description")&IF(NOT(ISBLANK(F35))," -> "&CHAR(10)&VLOOKUP(F35,AttackRiskStep!$A$3:$C$99,3,FALSE),"")&IF(NOT(ISBLANK(G35))," -> "&CHAR(10)&VLOOKUP(G35,AttackRiskStep!$A$3:$C$99,3,FALSE),"") -> see Description | P35: =VLOOKUP($N35,Likelihood!$A$3:$B$7,2,FALSE)*VLOOKUP($O35,Impact!$A$4:$B$8,2,FALSE) -> #N/A | Q35: =VLOOKUP(P35,RPN!$B$6:$C$22,2) -> #N/A | Z35: =VLOOKUP($N35,Likelihood!$A$3:$C$7,2,FALSE)+RANDBETWEEN(-20,20)/100 -> #N/A | AA35: =IF($Q35=AA$2,VLOOKUP($O35,Impact!$A$4:$B$8,2,FALSE)+RANDBETWEEN(-20,20)/100,NA()) -> #N/A | AB35: =IF($Q35=AB$2,VLOOKUP($O35,Impact!$A$4:$B$8,2,FALSE)+RANDBETWEEN(-20,20)/100,NA()) -> #N/A | AC35: =IF($Q35=AC$2,VLOOKUP($O35,Impact!$A$4:$B$8,2,FALSE)+RANDBETWEEN(-20,20)/100,NA()) -> #N/A
A36: 34 | B36: =I36 | H36: =IF(ISBLANK(E36),"s. D.",IF(ISBLANK(F36),E36,IF(ISBLANK(G36),F36,G36))) -> s. D. | I36: =IF(NOT(ISBLANK(E36)),E36,"")&IF(NOT(ISBLANK(F36))," -> "&F36,"")&IF(NOT(ISBLANK(G36))," -> "&G36,"") | J36: =I36&IF(NOT(ISBLANK(E36)),CHAR(10)&VLOOKUP(E36,AttackRiskStep!$A$3:$C$99,3,FALSE),"see Description")&IF(NOT(ISBLANK(F36))," -> "&CHAR(10)&VLOOKUP(F36,AttackRiskStep!$A$3:$C$99,3,FALSE),"")&IF(NOT(ISBLANK(G36))," -> "&CHAR(10)&VLOOKUP(G36,AttackRiskStep!$A$3:$C$99,3,FALSE),"") -> see Description | P36: =VLOOKUP($N36,Likelihood!$A$3:$B$7,2,FALSE)*VLOOKUP($O36,Impact!$A$4:$B$8,2,FALSE) -> #N/A | Q36: =VLOOKUP(P36,RPN!$B$6:$C$22,2) -> #N/A | Z36: =VLOOKUP($N36,Likelihood!$A$3:$C$7,2,FALSE)+RANDBETWEEN(-20,20)/100 -> #N/A | AA36: =IF($Q36=AA$2,VLOOKUP($O36,Impact!$A$4:$B$8,2,FALSE)+RANDBETWEEN(-20,20)/100,NA()) -> #N/A | AB36: =IF($Q36=AB$2,VLOOKUP($O36,Impact!$A$4:$B$8,2,FALSE)+RANDBETWEEN(-20,20)/100,NA()) -> #N/A | AC36: =IF($Q36=AC$2,VLOOKUP($O36,Impact!$A$4:$B$8,2,FALSE)+RANDBETWEEN(-20,20)/100,NA()) -> #N/A
A37: 35 | B37: =I37 | H37: =IF(ISBLANK(E37),"s. D.",IF(ISBLANK(F37),E37,IF(ISBLANK(G37),F37,G37))) -> s. D. | I37: =IF(NOT(ISBLANK(E37)),E37,"")&IF(NOT(ISBLANK(F37))," -> "&F37,"")&IF(NOT(ISBLANK(G37))," -> "&G37,"") | J37: =I37&IF(NOT(ISBLANK(E37)),CHAR(10)&VLOOKUP(E37,AttackRiskStep!$A$3:$C$99,3,FALSE),"see Description")&IF(NOT(ISBLANK(F37))," -> "&CHAR(10)&VLOOKUP(F37,AttackRiskStep!$A$3:$C$99,3,FALSE),"")&IF(NOT(ISBLANK(G37))," -> "&CHAR(10)&VLOOKUP(G37,AttackRiskStep!$A$3:$C$99,3,FALSE),"") -> see Description | P37: =VLOOKUP($N37,Likelihood!$A$3:$B$7,2,FALSE)*VLOOKUP($O37,Impact!$A$4:$B$8,2,FALSE) -> #N/A | Q37: =VLOOKUP(P37,RPN!$B$6:$C$22,2) -> #N/A | Z37: =VLOOKUP($N37,Likelihood!$A$3:$C$7,2,FALSE)+RANDBETWEEN(-20,20)/100 -> #N/A | AA37: =IF($Q37=AA$2,VLOOKUP($O37,Impact!$A$4:$B$8,2,FALSE)+RANDBETWEEN(-20,20)/100,NA()) -> #N/A | AB37: =IF($Q37=AB$2,VLOOKUP($O37,Impact!$A$4:$B$8,2,FALSE)+RANDBETWEEN(-20,20)/100,NA()) -> #N/A | AC37: =IF($Q37=AC$2,VLOOKUP($O37,Impact!$A$4:$B$8,2,FALSE)+RANDBETWEEN(-20,20)/100,NA()) -> #N/A
A38: 36 | B38: =I38 | H38: =IF(ISBLANK(E38),"s. D.",IF(ISBLANK(F38),E38,IF(ISBLANK(G38),F38,G38))) -> s. D. | I38: =IF(NOT(ISBLANK(E38)),E38,"")&IF(NOT(ISBLANK(F38))," -> "&F38,"")&IF(NOT(ISBLANK(G38))," -> "&G38,"") | J38: =I38&IF(NOT(ISBLANK(E38)),CHAR(10)&VLOOKUP(E38,AttackRiskStep!$A$3:$C$99,3,FALSE),"see Description")&IF(NOT(ISBLANK(F38))," -> "&CHAR(10)&VLOOKUP(F38,AttackRiskStep!$A$3:$C$99,3,FALSE),"")&IF(NOT(ISBLANK(G38))," -> "&CHAR(10)&VLOOKUP(G38,AttackRiskStep!$A$3:$C$99,3,FALSE),"") -> see Description | P38: =VLOOKUP($N38,Likelihood!$A$3:$B$7,2,FALSE)*VLOOKUP($O38,Impact!$A$4:$B$8,2,FALSE) -> #N/A | Q38: =VLOOKUP(P38,RPN!$B$6:$C$22,2) -> #N/A | Z38: =VLOOKUP($N38,Likelihood!$A$3:$C$7,2,FALSE)+RANDBETWEEN(-20,20)/100 -> #N/A | AA38: =IF($Q38=AA$2,VLOOKUP($O38,Impact!$A$4:$B$8,2,FALSE)+RANDBETWEEN(-20,20)/100,NA()) -> #N/A | AB38: =IF($Q38=AB$2,VLOOKUP($O38,Impact!$A$4:$B$8,2,FALSE)+RANDBETWEEN(-20,20)/100,NA()) -> #N/A | AC38: =IF($Q38=AC$2,VLOOKUP($O38,Impact!$A$4:$B$8,2,FALSE)+RANDBETWEEN(-20,20)/100,NA()) -> #N/A
A39: 37 | B39: =I39 | H39: =IF(ISBLANK(E39),"s. D.",IF(ISBLANK(F39),E39,IF(ISBLANK(G39),F39,G39))) -> s. D. | I39: =IF(NOT(ISBLANK(E39)),E39,"")&IF(NOT(ISBLANK(F39))," -> "&F39,"")&IF(NOT(ISBLANK(G39))," -> "&G39,"") | J39: =I39&IF(NOT(ISBLANK(E39)),CHAR(10)&VLOOKUP(E39,AttackRiskStep!$A$3:$C$99,3,FALSE),"see Description")&IF(NOT(ISBLANK(F39))," -> "&CHAR(10)&VLOOKUP(F39,AttackRiskStep!$A$3:$C$99,3,FALSE),"")&IF(NOT(ISBLANK(G39))," -> "&CHAR(10)&VLOOKUP(G39,AttackRiskStep!$A$3:$C$99,3,FALSE),"") -> see Description | P39: =VLOOKUP($N39,Likelihood!$A$3:$B$7,2,FALSE)*VLOOKUP($O39,Impact!$A$4:$B$8,2,FALSE) -> #N/A | Q39: =VLOOKUP(P39,RPN!$B$6:$C$22,2) -> #N/A | Z39: =VLOOKUP($N39,Likelihood!$A$3:$C$7,2,FALSE)+RANDBETWEEN(-20,20)/100 -> #N/A | AA39: =IF($Q39=AA$2,VLOOKUP($O39,Impact!$A$4:$B$8,2,FALSE)+RANDBETWEEN(-20,20)/100,NA()) -> #N/A | AB39: =IF($Q39=AB$2,VLOOKUP($O39,Impact!$A$4:$B$8,2,FALSE)+RANDBETWEEN(-20,20)/100,NA()) -> #N/A | AC39: =IF($Q39=AC$2,VLOOKUP($O39,Impact!$A$4:$B$8,2,FALSE)+RANDBETWEEN(-20,20)/100,NA()) -> #N/A
A40: 38 | B40: =I40 | H40: =IF(ISBLANK(E40),"s. D.",IF(ISBLANK(F40),E40,IF(ISBLANK(G40),F40,G40))) -> s. D. | I40: =IF(NOT(ISBLANK(E40)),E40,"")&IF(NOT(ISBLANK(F40))," -> "&F40,"")&IF(NOT(ISBLANK(G40))," -> "&G40,"") | J40: =I40&IF(NOT(ISBLANK(E40)),CHAR(10)&VLOOKUP(E40,AttackRiskStep!$A$3:$C$99,3,FALSE),"see Description")&IF(NOT(ISBLANK(F40))," -> "&CHAR(10)&VLOOKUP(F40,AttackRiskStep!$A$3:$C$99,3,FALSE),"")&IF(NOT(ISBLANK(G40))," -> "&CHAR(10)&VLOOKUP(G40,AttackRiskStep!$A$3:$C$99,3,FALSE),"") -> see Description | P40: =VLOOKUP($N40,Likelihood!$A$3:$B$7,2,FALSE)*VLOOKUP($O40,Impact!$A$4:$B$8,2,FALSE) -> #N/A | Q40: =VLOOKUP(P40,RPN!$B$6:$C$22,2) -> #N/A | Z40: =VLOOKUP($N40,Likelihood!$A$3:$C$7,2,FALSE)+RANDBETWEEN(-20,20)/100 -> #N/A | AA40: =IF($Q40=AA$2,VLOOKUP($O40,Impact!$A$4:$B$8,2,FALSE)+RANDBETWEEN(-20,20)/100,NA()) -> #N/A | AB40: =IF($Q40=AB$2,VLOOKUP($O40,Impact!$A$4:$B$8,2,FALSE)+RANDBETWEEN(-20,20)/100,NA()) -> #N/A | AC40: =IF($Q40=AC$2,VLOOKUP($O40,Impact!$A$4:$B$8,2,FALSE)+RANDBETWEEN(-20,20)/100,NA()) -> #N/A
...

Sheet AttackRiskStep
A1: Attack step
A2: ID | B2: Original description | C2: Product related description | D2: Detailed description
A3: AS1 | B3: Gain access to a trusted operational environment | C3: =SUBSTITUTE(SUBSTITUTE(B3,"company",Info!$B$1),"product",Info!$B$2) -> Gain access to a trusted operational environment
A4: AS2 | B4: Gain access to a local network | C4: =SUBSTITUTE(SUBSTITUTE(B4,"company",Info!$B$1),"product",Info!$B$2) -> Gain access to a local network
A5: AS3 | B5: Compromising the product using a software vulnerability | C5: =SUBSTITUTE(SUBSTITUTE(B5,"company",Info!$B$1),"product",Info!$B$2) -> Compromising the EC-Master stack using a software vulnerability | D5: infinite loop, race condition, memory leaks, out-of-memory, lock-up, crash
A6: AS4 | B6: Interrupting the product with a Denial of Service (DoS) attack | C6: =SUBSTITUTE(SUBSTITUTE(B6,"company",Info!$B$1),"product",Info!$B$2) -> Interrupting the EC-Master stack with a Denial of Service (DoS) attack
A7: AS5 | B7: Eavesdropping on the product's communication | C7: =SUBSTITUTE(SUBSTITUTE(B7,"company",Info!$B$1),"product",Info!$B$2) -> Eavesdropping on the EC-Master stack's communication
A8: AS6 | B8: Spoofing / tampering with the product's outgoing communication | C8: =SUBSTITUTE(SUBSTITUTE(B8,"company",Info!$B$1),"product",Info!$B$2) -> Spoofing / tampering with the EC-Master stack's outgoing communication
A9: AS7 | B9: Spoofing / tampering with the product's incoming communication | C9: =SUBSTITUTE(SUBSTITUTE(B9,"company",Info!$B$1),"product",Info!$B$2) -> Spoofing / tampering with the EC-Master stack's incoming communication
A10: AS8 | B10: Disrupting the product's communication over the wireless network | C10: =SUBSTITUTE(SUBSTITUTE(B10,"company",Info!$B$1),"product",Info!$B$2) -> Disrupting the EC-Master stack's communication over the wireless network
A11: AS9 | B11: Attacking the product's internal gateway from the Internet | C11: =SUBSTITUTE(SUBSTITUTE(B11,"company",Info!$B$1),"product",Info!$B$2) -> Attacking the EC-Master stack's internal gateway from the Internet
A12: AS10 | B12: Attacking devices in the customer's network | C12: =SUBSTITUTE(SUBSTITUTE(B12,"company",Info!$B$1),"product",Info!$B$2) -> Attacking devices in the customer's network
A13: AS11 | B13: Denial of Service (DoS) on the customer's network | C13: =SUBSTITUTE(SUBSTITUTE(B13,"company",Info!$B$1),"product",Info!$B$2) -> Denial of Service (DoS) on the customer's network
A14: AS12 | B14: Compromising an untrusted device that communicates directly with the product | C14: =SUBSTITUTE(SUBSTITUTE(B14,"company",Info!$B$1),"product",Info!$B$2) -> Compromising an untrusted device that communicates directly with the EC-Master stack
A15: AS13 | B15: Attacking the product or its communication from an untrusted local network | C15: =SUBSTITUTE(SUBSTITUTE(B15,"company",Info!$B$1),"product",Info!$B$2) -> Attacking the EC-Master stack or its communication from an untrusted local network
A16: AS14 | B16: Disrupting the product's communication over the local network | C16: =SUBSTITUTE(SUBSTITUTE(B16,"company",Info!$B$1),"product",Info!$B$2) -> Disrupting the EC-Master stack's communication over the local network
A17: AS15 | B17: Attacking the product from the Internet or a mobile network | C17: =SUBSTITUTE(SUBSTITUTE(B17,"company",Info!$B$1),"product",Info!$B$2) -> Attacking the EC-Master stack from the Internet or a mobile network
... A44: AS42 | B44: Circumvention of licence provisions or bypassing of licensing procedures | C44: =SUBSTITUTE(SUBSTITUTE(B44,"company",Info!$B$1),"product",Info!$B$2) -> Circumvention of licence provisions or bypassing of licensing procedures

Sheet DamageCategory
A1: Damage Category
A2: Personal Data
A3: Loss of Intellectual Property
A4: Financial and Legal
A5: Safety and Security
A6: Function and Availability

Sheet Stakeholder
A1: Stakeholder
A2: acontis
A3: customer

Sheet Likelihood
A1: Likelihood
A2: Titel | B2: Level | C2: Description
A3: Negligible | B3: 1 | C3: Extremely rare; may occur only in exceptional circumstances (< 1% chance)
A4: Unlikely | B4: 2 | C4: Not expected to occur; has happened elsewhere but not here (1–10% chance)
A5: Possible | B5: 3 | C5: Might occur at some time; has happened here before (10–50% chance)
A6: Likely | B6: 4 | C6: Will probably occur in most circumstances; frequent history (50–90% chance)
A7: Frequent | B7: 5 | C7: Expected to occur almost constantly or multiple times a year (> 90% chance)

Sheet Impact
A1: Impact
A2: Titel | B2: Level | C2: Description
C3: =DamageCategory!$A$2 -> Personal Data | D3: =DamageCategory!$A$3 -> Loss of Intellectual Property | E3: =DamageCategory!$A$4 -> Financial and Legal | F3: =DamageCategory!$A$5 -> Safety and Security | G3: =DamageCategory!$A$6 -> Function and Availability
A4: Negligible | B4: 1 | C4: Non-sensitive data leaked; no privacy breach. | D4: Minor trade secret leak with no market impact. | E4: Minimal cost (<$1k); no legal repercussions. | F4: No injury; no security breach. | G4: Brief flicker in service (<1 min); no user impact.
A5: Minor | B5: 2 | C5: Minor breach of non-critical personal info. | D5: Leak of internal process docs; slight edge lost. | E5: Small loss; minor breach of contract/fine. | F5: Minor injury (First Aid); localized security gap. | G5: Minor slowdown; "annoyance" level for users.
A6: Moderate | B6: 3 | C6: Significant breach of PII (Names, Emails). | D6: Loss of a patented process or key strategy. | E6: Noticeable loss; lawsuit potential; regulatory audit. | F6: Medical treatment required; breach of secure areas. | G6: Significant downtime (hours); core functions degraded.
A7: Major | B7: 4 | C7: Mass breach of sensitive data (SSNs, Health). | D7: Loss of core product IP; loss of competitive advantage. | E7: Heavy fines; major lawsuit; brand damage. | F7: Severe injury; critical infrastructure compromised. | G7: Major outage (days); business operations halted.
A8: Catastrophic | B8: 5 | C8: Global data privacy violation; massive identity theft. | D8: Full "Crown Jewels" loss; company can no longer compete. | E8: Insolvency; criminal charges; loss of license. | F8: Fatality or life-threatening event; total security failure. | G8: Permanent loss of data or permanent system shutdown.

Sheet RPN
A1: Start | B1: End | C1: RPN Cat.
A2: 1 | B2: 6 | C2: Low
A3: =B2+1 -> 7 | B3: 12 | C3: Medium
A4: =B3+1 -> 13 | B4: 25 | C4: High
B6: 0 | C6: =IF(B6<$B$2,$C$2,IF(B6<=$B$3,$C$3,$C$4)) -> Low | E6: 5 | F6: =$E6*F$11 -> 5 | G6: =$E6*G$11 -> 10 | H6: =$E6*H$11 -> 15 | I6: =$E6*I$11 -> 20 | J6: =$E6*J$11 -> 25
B7: 1 | C7: =IF(B7<$B$2,$C$2,IF(B7<=$B$3,$C$3,$C$4)) -> Low | E7: 4 | F7: =$E7*F$11 -> 4 | G7: =$E7*G$11 -> 8 | H7: =$E7*H$11 -> 12 | I7: =$E7*I$11 -> 16 | J7: =$E7*J$11 -> 20
B8: 2 | C8: =IF(B8<$B$2,$C$2,IF(B8<=$B$3,$C$3,$C$4)) -> Low | E8: 3 | F8: =$E8*F$11 -> 3 | G8: =$E8*G$11 -> 6 | H8: =$E8*H$11 -> 9 | I8: =$E8*I$11 -> 12 | J8: =$E8*J$11 -> 15
